Workbook

Sheet README
A1: 美債 Vol 監控：RV、IV − RV 與 Kim-Wright TP
A3: 使用步驟
A4: 1. 在已登入 Bloomberg 的電腦上用 Excel 開啟本檔（需 Bloomberg Excel Add-in）。
A5: 2. 到 Settings 分頁，檢查黃底藍字的輸入格：起訖日期、ticker、RV 視窗。
A6: 3. 3m10y Swaption Normal Vol 的 ticker 請到 VCUB <GO> 找 3M × 10Y（Normal / bp）那格，取得 ticker 後填入 Settings!B9。
A7: 4. 按 Bloomberg 工具列的 Refresh Workbook（或 Ctrl+Alt+Shift+R）讓 BBG_Data 的 BDH 抓資料，Calc 與 Dashboard 會自動計算。
A9: 分頁說明
A10: Settings：所有輸入參數（黃底藍字＝可修改）。
A11: BBG_Data：BDH 公式抓取的原始資料。每個 ticker 佔兩欄（日期、數值），Calc 依日期精確比對，不依列對齊。
A12: KW_TP：Kim-Wright 10Y Term Premium（FRED：THREEFYTP10），使用者下載的靜態資料，最後一筆 2026-09-25。
A13: DKW_10Y：D'Amico-Kim-Wei 10Y 拆解（Fed staff，每月更新），最後一筆 2026-08-31。名目殖利率 = 預期實質短率 + 實質 TP + 預期通膨 + 通膨風險溢酬；名目 TP = 實質 TP + 通膨風險溢酬。
A14: Calc：每日變動（bp）、滾動 RV、IV − RV、事後 VRP、Kim-Wright TP 對照、10Y = TIPS + BEI 的拆解，以及 DKW 各成分相對基準日的變動。
... A36: • Calc 預留 1500 列；若起始日期太早導致資料超過，請把 Calc 最後一列公式往下複製。

Sheet Settings
A1: 參數設定
A2: 項目 | B2: 值 | C2: 說明
A3: 起始日期 | B3: 45292 | C3: BDH 起始日。RV 63 日需要約 3 個月暖機，建議比觀察期早至少 3 個月。
A4: 結束日期 | B4: =TODAY() | C4: 預設今天，可改成固定日期。
A6: 10Y 公債殖利率 ticker | B6: USGG10YR Index | C6: Bloomberg 10Y 公債殖利率，單位 %。
A7: 10Y SOFR Swap ticker | B7: USOSFR10 Curncy | C7: 10Y SOFR OIS Swap，單位 %。請在 Terminal 確認 ticker。
A8: MOVE ticker | B8: MOVE Index | C8: ICE BofA MOVE Index，單位 bp。
A9: 3m10y Swaption Normal Vol ticker | C9: 請從 VCUB <GO> 取得 3M×10Y Normal Vol（bp/y）的 ticker 填入；留空則略過 Swaption 相關計算。
A11: 短期 RV 視窗（交易日） | B11: 21 | C11: 約 1 個月，對應 MOVE（1 個月期選擇權）。
A12: 長期 RV 視窗（交易日） | B12: 63 | C12: 約 3 個月，對應 3m10y Swaption。
A13: 年化天數 | B13: 252 | C13: 年化 = 日標準差 × √年化天數。
A14: 10Y TIPS 實質殖利率 ticker | B14: USGGT10Y Index | C14: 10Y TIPS 殖利率（實質利率，市場口徑），單位 %。請在 Terminal 確認 ticker。
A15: 10Y BEI ticker | B15: USGGBE10 Index | C15: 10Y Breakeven Inflation，單位 %。請在 Terminal 確認 ticker。
A16: 分解基準日 | B16: 46022 | C16: 計算「相對基準日的變動」的起點，例如前一年底或開戰日。
A17: 基準日所在列（自動） | B17: =SUMPRODUCT(MAX(ISNUMBER(Calc!$A$2:$A$1501)*(Calc!$A$2:$A$1501<=$B$16)*ROW(Calc!$A$2:$A$1501))) | C17: Calc 中日期 ≤ 基準日的最後一列；0 代表基準日早於資料起點。
A18: 2Y 公債殖利率 ticker | B18: USGG2YR Index | C18: 單位 %。
A19: 5Y 公債殖利率 ticker | B19: USGG5YR Index | C19: 單位 %。
A20: 30Y 公債殖利率 ticker | B20: USGG30YR Index | C20: 單位 %。
A21: HY OAS ticker | B21: LF98OAS Index | C21: Bloomberg US Corporate High Yield OAS。
A22: IG OAS ticker | B22: LUACOAS Index | C22: Bloomberg US Corporate IG OAS。
A23: CDX IG 5Y ticker | B23: IBOXUMAE CBBT Curncy | C23: 單位 bp。
A24: CDX HY 5Y ticker | B24: IBOXHYSE CBBT Curncy | C24: 單位 bp（spread）。
A25: OAS 換算倍數 | B25: 100 | C25: BBG 回傳 % 時填 100（3.18 → 318 bp）；已是 bp 則填 1。
A26: RV 最少有效筆數比例 | B26: 0.85 | C26: 視窗內有效（非 0）變動至少要有視窗長度 × 此比例，否則顯示 N/A。
A28: 圖例：黃底藍字＝可修改的輸入；黑字＝公式；綠字＝引用其他分頁。
A29: 範例：10Y 公債殖利率 ticker 填 USGG10YR Index；RV 視窗填整數，例如 21。

Sheet BBG_Data
A1: 10Y 公債殖利率 日期 | B1: 10Y 公債殖利率 (%) | C1: 10Y SOFR Swap 日期 | D1: 10Y SOFR Swap (%) | E1: MOVE 日期 | F1: MOVE (bp) | G1: 3m10y Swaption IV 日期 | H1: 3m10y Swaption IV (bp/y) | I1: 10Y TIPS 實質殖利率 日期 | J1: 10Y TIPS 實質殖利率 (%) | K1: 10Y BEI 日期 | L1: 10Y BEI (%) | M1: 2Y 公債殖利率 日期 | N1: 2Y 公債殖利率 (%) | O1: 5Y 公債殖利率 日期 | P1: 5Y 公債殖利率 (%) | Q1: 30Y 公債殖利率 日期 | R1: 30Y 公債殖利率 (%) | S1: HY OAS 日期 | T1: HY OAS（BBG 原始單位） | U1: IG OAS 日期 | V1: IG OAS（BBG 原始單位） | W1: CDX IG 5Y 日期 | X1: CDX IG 5Y (bp) | Y1: CDX HY 5Y 日期 | Z1: CDX HY 5Y (bp) | AB1: 說明
A2: =BDH(Settings!$B$6,"PX_LAST",Settings!$B$3,Settings!$B$4,"Dts=S","Days=W","Fill=P") | C2: =BDH(Settings!$B$7,"PX_LAST",Settings!$B$3,Settings!$B$4,"Dts=S","Days=W","Fill=P") | E2: =BDH(Settings!$B$8,"PX_LAST",Settings!$B$3,Settings!$B$4,"Dts=S","Days=W","Fill=P") | G2: =IF(Settings!$B$9="","",BDH(Settings!$B$9,"PX_LAST",Settings!$B$3,Settings!$B$4,"Dts=S","Days=W","Fill=P")) | I2: =BDH(Settings!$B$14,"PX_LAST",Settings!$B$3,Settings!$B$4,"Dts=S","Days=W","Fill=P") | K2: =BDH(Settings!$B$15,"PX_LAST",Settings!$B$3,Settings!$B$4,"Dts=S","Days=W","Fill=P") | M2: =BDH(Settings!$B$18,"PX_LAST",Settings!$B$3,Settings!$B$4,"Dts=S","Days=W","Fill=P") | O2: =BDH(Settings!$B$19,"PX_LAST",Settings!$B$3,Settings!$B$4,"Dts=S","Days=W","Fill=P") | Q2: =BDH(Settings!$B$20,"PX_LAST",Settings!$B$3,Settings!$B$4,"Dts=S","Days=W","Fill=P") | S2: =BDH(Settings!$B$21,"PX_LAST",Settings!$B$3,Settings!$B$4,"Dts=S","Days=W","Fill=P") | U2: =BDH(Settings!$B$22,"PX_LAST",Settings!$B$3,Settings!$B$4,"Dts=S","Days=W","Fill=P") | W2: =BDH(Settings!$B$23,"PX_LAST",Settings!$B$3,Settings!$B$4,"Dts=S","Days=W","Fill=P") | Y2: =BDH(Settings!$B$24,"PX_LAST",Settings!$B$3,Settings!$B$4,"Dts=S","Days=W","Fill=P") | AB2: 每組 BDH 輸出兩欄：日期（Dts=S）與數值；Calc 用日期精確比對（MATCH），不依列對齊。
AB3: 原因：MOVE 等指數即使指定 Days=W，Bloomberg 仍可能回傳每個日曆日，依列對齊會錯位。
AB4: 每組預留 3999 列；請勿在公式下方輸入任何內容，以免擋住 BDH 輸出。

Sheet KW_TP
A1: 日期 | B1: Kim-Wright 10Y TP (%) | C1: Kim-Wright 10Y TP (bp) | E1: 來源：FRED 序列 THREEFYTP10（Kim-Wright 三因子模型 10Y Term Premium），由使用者下載；已刪除空值（假日）。
A2: 42639 | B2: -0.1102 | C2: =B2*100
A3: 42640 | B3: -0.1259 | C3: =B3*100
A4: 42641 | B4: -0.1292 | C4: =B4*100
A5: 42642 | B5: -0.1354 | C5: =B5*100
A6: 42643 | B6: -0.1248 | C6: =B6*100
A7: 42646 | B7: -0.1135 | C7: =B7*100
A8: 42647 | B8: -0.0916 | C8: =B8*100
A9: 42648 | B9: -0.0722 | C9: =B9*100
A10: 42649 | B10: -0.0527 | C10: =B10*100
A11: 42650 | B11: -0.0558 | C11: =B11*100
A12: 42654 | B12: -0.0436 | C12: =B12*100
A13: 42655 | B13: -0.0377 | C13: =B13*100
... A2501: 46290 | B2501: 1.0203 | C2501: =B2501*100

Sheet DKW_10Y
A1: 日期 | B1: 預期實質短率 (%) | C1: 實質 TP (%) | D1: 預期通膨 (%) | E1: 通膨風險溢酬 (%) | F1: TIPS 流動性溢酬 (%) | G1: 名目殖利率 fitted (%) | H1: 名目 TP (%) | J1: 來源：Fed staff DKW_updates.csv（D'Amico, Kim & Wei 2018；Kim, Walsh & Wei 2019 FEDS Notes），由使用者下載；只保留 2015-01-01 之後且四個成分齊全的日期。非 Fed 官方統計，可能修正。
A2: 42006 | B2: -0.26559999 | C2: 0.21789999 | D2: 2.2083001 | E2: 0.022799801 | F2: 0.59020001 | G2: 2.1833999 | H2: =C2+E2
A3: 42009 | B3: -0.2865 | C3: 0.1894 | D3: 2.1902001 | E3: 0.016599871 | F3: 0.62190002 | G3: 2.1097 | H3: =C3+E3
A4: 42010 | B4: -0.30770001 | C4: 0.16230001 | D4: 2.1733999 | E4: 0.010400012 | F4: 0.66420001 | G4: 2.0383999 | H4: =C4+E4
A5: 42011 | B5: -0.31439999 | C5: 0.15629999 | D5: 2.1694 | E5: 0.0089999288 | F5: 0.65859997 | G5: 2.0202999 | H5: =C5+E5
A6: 42012 | B6: -0.30119999 | C6: 0.18009999 | D6: 2.1837001 | E6: 0.014299922 | F6: 0.63020003 | G6: 2.0769 | H6: =C6+E6
A7: 42013 | B7: -0.31469999 | C7: 0.16689999 | D7: 2.1754999 | E7: 0.011100084 | F7: 0.61339998 | G7: 2.0388 | H7: =C7+E7
A8: 42016 | B8: -0.33050001 | C8: 0.1462 | D8: 2.1635001 | E8: 0.0060998797 | F8: 0.63739997 | G8: 1.9852999 | H8: =C8+E8
A9: 42017 | B9: -0.3348 | C9: 0.1444 | D9: 2.1624 | E9: 0.005499959 | F9: 0.65869999 | G9: 1.9775 | H9: =C9+E9
A10: 42018 | B10: -0.3502 | C10: 0.1232 | D10: 2.1500001 | E10: 0.00039994717 | F10: 0.61299998 | G10: 1.9234 | H10: =C10+E10
A11: 42019 | B11: -0.3798 | C11: 0.092100002 | D11: 2.1307001 | E11: -0.0071001649 | F11: 0.57429999 | G11: 1.8358999 | H11: =C11+E11
A12: 42020 | B12: -0.35830001 | C12: 0.1185 | D12: 2.1471 | E12: -0.0010000169 | F12: 0.57050002 | G12: 1.9062999 | H12: =C12+E12
A13: 42024 | B13: -0.3551 | C13: 0.1165 | D13: 2.1461 | E13: -0.0012999922 | F13: 0.5704 | G13: 1.9062001 | H13: =C13+E13
... A2918: 46265 | B2918: 1.1527 | C2918: 0.78119999 | D2918: 2.8006999 | E2918: 0.10850012 | F2918: 0.41159999 | G2918: 4.8431001 | H2918: =C2918+E2918

Sheet Calc
A1: 日期 | B1: 10Y 公債 (%) | C1: 10Y Swap (%) | D1: MOVE (bp) | E1: Swaption IV (bp/y) | F1: Δ 10Y 公債 (bp) | G1: Δ 10Y Swap (bp) | H1: RV 公債 短期 (bp/y) | I1: RV 公債 長期 (bp/y) | J1: RV Swap 短期 (bp/y) | K1: RV Swap 長期 (bp/y) | L1: MOVE − RV 公債短期 | M1: Swaption IV − RV Swap 長期 | N1: 未來長期視窗 Swap RV (bp/y) | O1: 事後 VRP：Swaption IV − 未來 RV | P1: Kim-Wright TP (bp) | Q1: 10Y TIPS (%) | R1: 10Y BEI (%) | S1: 檢查：名目 − TIPS − BEI (bp) | T1: Δ10Y 名目 相對基準日 (bp) | U1: ΔTIPS 實質利率貢獻 (bp) | V1: ΔBEI 通膨預期貢獻 (bp) | W1: ΔKim-Wright TP 相對基準日 (bp) | X1: DKW Δ預期實質短率 (bp) | Y1: DKW Δ實質 TP (bp) | Z1: DKW Δ預期通膨 (bp) | AA1: DKW Δ通膨風險溢酬 (bp) | AB1: DKW Δ名目 TP (bp) | AC1: 2Y 公債 (%) | AD1: 5Y 公債 (%) | AE1: 30Y 公債 (%) | AF1: 2s10s (bp) | AG1: 5s30s (bp) | AH1: HY OAS (bp) | AI1: IG OAS (bp) | AJ1: CDX IG 5Y (bp) | AK1: CDX HY 5Y (bp)
A2: =IF(ISNUMBER(BBG_Data!A2),BBG_Data!A2,"") | B2: =IF(AND(ISNUMBER($A2),ISNUMBER(BBG_Data!B2)),BBG_Data!B2,NA()) | C2: =IF(NOT(ISNUMBER($A2)),NA(),IFERROR(1*INDEX(BBG_Data!$D$2:$D$4000,MATCH($A2,BBG_Data!$C$2:$C$4000,0)),NA())) | D2: =IF(NOT(ISNUMBER($A2)),NA(),IFERROR(1*INDEX(BBG_Data!$F$2:$F$4000,MATCH($A2,BBG_Data!$E$2:$E$4000,0)),NA())) | E2: =IF(NOT(ISNUMBER($A2)),NA(),IFERROR(1*INDEX(BBG_Data!$H$2:$H$4000,MATCH($A2,BBG_Data!$G$2:$G$4000,0)),NA())) | F2: ="" | G2: ="" | H2: =IF(OR(NOT(ISNUMBER($A2)),ROW()-2<Settings!$B$11),NA(),IF(COUNT(OFFSET(F2,1-Settings!$B$11,0,Settings!$B$11,1))<ROUNDUP(Settings!$B$11*Settings!$B$26,0),NA(),STDEV(OFFSET(F2,1-Settings!$B$11,0,Settings!$B$11,1))*SQRT(Settings!$B$13))) | I2: =IF(OR(NOT(ISNUMBER($A2)),ROW()-2<Settings!$B$12),NA(),IF(COUNT(OFFSET(F2,1-Settings!$B$12,0,Settings!$B$12,1))<ROUNDUP(Settings!$B$12*Settings!$B$26,0),NA(),STDEV(OFFSET(F2,1-Settings!$B$12,0,Settings!$B$12,1))*SQRT(Settings!$B$13))) | J2: =IF(OR(NOT(ISNUMBER($A2)),ROW()-2<Settings!$B$11),NA(),IF(COUNT(OFFSET(G2,1-Settings!$B$11,0,Settings!$B$11,1))<ROUNDUP(Settings!$B$11*Settings!$B$26,0),NA(),STDEV(OFFSET(G2,1-Settings!$B$11,0,Settings!$B$11,1))*SQRT(Settings!$B$13))) | K2: =IF(OR(NOT(ISNUMBER($A2)),ROW()-2<Settings!$B$12),NA(),IF(COUNT(OFFSET(G2,1-Settings!$B$12,0,Settings!$B$12,1))<ROUNDUP(Settings!$B$12*Settings!$B$26,0),NA(),STDEV(OFFSET(G2,1-Settings!$B$12,0,Settings!$B$12,1))*SQRT(Settings!$B$13))) | L2: =IF(AND(ISNUMBER(D2),ISNUMBER(H2)),D2-H2,NA()) | M2: =IF(AND(ISNUMBER(E2),ISNUMBER(K2)),E2-K2,NA()) | N2: =IF(NOT(ISNUMBER($A2)),NA(),IF(COUNT(OFFSET(G2,1,0,Settings!$B$12,1))<ROUNDUP(Settings!$B$12*Settings!$B$26,0),NA(),STDEV(OFFSET(G2,1,0,Settings!$B$12,1))*SQRT(Settings!$B$13))) | O2: =IF(AND(ISNUMBER(E2),ISNUMBER(N2)),E2-N2,NA()) | P2: =IF(NOT(ISNUMBER($A2)),NA(),IF(OR($A2<MIN(KW_TP!$A$2:$A$2501),$A2>MAX(KW_TP!$A$2:$A$2501)),NA(),INDEX(KW_TP!$C$2:$C$2501,MATCH($A2,KW_TP!$A$2:$A$2501,1)))) | Q2: =IF(NOT(ISNUMBER($A2)),NA(),IFERROR(1*INDEX(BBG_Data!$J$2:$J$4000,MATCH($A2,BBG_Data!$I$2:$I$4000,0)),NA())) | R2: =IF(NOT(ISNUMBER($A2)),NA(),IFERROR(1*INDEX(BBG_Data!$L$2:$L$4000,MATCH($A2,BBG_Data!$K$2:$K$4000,0)),NA())) | S2: =IF(AND(ISNUMBER(B2),ISNUMBER(Q2),ISNUMBER(R2)),(B2-Q2-R2)*100,NA()) | T2: =IF(AND(ISNUMBER(B2),Settings!$B$17>0),IF(ISNUMBER(INDEX($B:$B,Settings!$B$17)),(B2-INDEX($B:$B,Settings!$B$17))*100,NA()),NA()) | U2: =IF(AND(ISNUMBER(Q2),Settings!$B$17>0),IF(ISNUMBER(INDEX($Q:$Q,Settings!$B$17)),(Q2-INDEX($Q:$Q,Settings!$B$17))*100,NA()),NA()) | V2: =IF(AND(ISNUMBER(R2),Settings!$B$17>0),IF(ISNUMBER(INDEX($R:$R,Settings!$B$17)),(R2-INDEX($R:$R,Settings!$B$17))*100,NA()),NA()) | W2: =IF(AND(ISNUMBER(P2),Settings!$B$17>0),IF(ISNUMBER(INDEX($P:$P,Settings!$B$17)),P2-INDEX($P:$P,Settings!$B$17),NA()),NA()) | X2: =IF(NOT(ISNUMBER($A2)),NA(),IF(OR($A2<MIN(DKW_10Y!$A$2:$A$2918),$A2>MAX(DKW_10Y!$A$2:$A$2918),Settings!$B$16<MIN(DKW_10Y!$A$2:$A$2918)),NA(),(INDEX(DKW_10Y!$B$2:$B$2918,MATCH($A2,DKW_10Y!$A$2:$A$2918,1))-INDEX(DKW_10Y!$B$2:$B$2918,MATCH(Settings!$B$16,DKW_10Y!$A$2:$A$2918,1)))*100)) | Y2: =IF(NOT(ISNUMBER($A2)),NA(),IF(OR($A2<MIN(DKW_10Y!$A$2:$A$2918),$A2>MAX(DKW_10Y!$A$2:$A$2918),Settings!$B$16<MIN(DKW_10Y!$A$2:$A$2918)),NA(),(INDEX(DKW_10Y!$C$2:$C$2918,MATCH($A2,DKW_10Y!$A$2:$A$2918,1))-INDEX(DKW_10Y!$C$2:$C$2918,MATCH(Settings!$B$16,DKW_10Y!$A$2:$A$2918,1)))*100)) | Z2: =IF(NOT(ISNUMBER($A2)),NA(),IF(OR($A2<MIN(DKW_10Y!$A$2:$A$2918),$A2>MAX(DKW_10Y!$A$2:$A$2918),Settings!$B$16<MIN(DKW_10Y!$A$2:$A$2918)),NA(),(INDEX(DKW_10Y!$D$2:$D$2918,MATCH($A2,DKW_10Y!$A$2:$A$2918,1))-INDEX(DKW_10Y!$D$2:$D$2918,MATCH(Settings!$B$16,DKW_10Y!$A$2:$A$2918,1)))*100)) | AA2: =IF(NOT(ISNUMBER($A2)),NA(),IF(OR($A2<MIN(DKW_10Y!$A$2:$A$2918),$A2>MAX(DKW_10Y!$A$2:$A$2918),Settings!$B$16<MIN(DKW_10Y!$A$2:$A$2918)),NA(),(INDEX(DKW_10Y!$E$2:$E$2918,MATCH($A2,DKW_10Y!$A$2:$A$2918,1))-INDEX(DKW_10Y!$E$2:$E$2918,MATCH(Settings!$B$16,DKW_10Y!$A$2:$A$2918,1)))*100)) | AB2: =IF(NOT(ISNUMBER($A2)),NA(),IF(OR($A2<MIN(DKW_10Y!$A$2:$A$2918),$A2>MAX(DKW_10Y!$A$2:$A$2918),Settings!$B$16<MIN(DKW_10Y!$A$2:$A$2918)),NA(),(INDEX(DKW_10Y!$H$2:$H$2918,MATCH($A2,DKW_10Y!$A$2:$A$2918,1))-INDEX(DKW_10Y!$H$2:$H$2918,MATCH(Settings!$B$16,DKW_10Y!$A$2:$A$2918,1)))*100)) | AC2: =IF(NOT(ISNUMBER($A2)),NA(),IFERROR(1*INDEX(BBG_Data!$N$2:$N$4000,MATCH($A2,BBG_Data!$M$2:$M$4000,0)),NA())) | AD2: =IF(NOT(ISNUMBER($A2)),NA(),IFERROR(1*INDEX(BBG_Data!$P$2:$P$4000,MATCH($A2,BBG_Data!$O$2:$O$4000,0)),NA())) | AE2: =IF(NOT(ISNUMBER($A2)),NA(),IFERROR(1*INDEX(BBG_Data!$R$2:$R$4000,MATCH($A2,BBG_Data!$Q$2:$Q$4000,0)),NA())) | AF2: =IF(AND(ISNUMBER(B2),ISNUMBER(AC2)),(B2-AC2)*100,NA()) | AG2: =IF(AND(ISNUMBER(AE2),ISNUMBER(AD2)),(AE2-AD2)*100,NA()) | AH2: =IF(NOT(ISNUMBER($A2)),NA(),IFERROR(INDEX(BBG_Data!$T$2:$T$4000,MATCH($A2,BBG_Data!$S$2:$S$4000,0))*Settings!$B$25,NA())) | AI2: =IF(NOT(ISNUMBER($A2)),NA(),IFERROR(INDEX(BBG_Data!$V$2:$V$4000,MATCH($A2,BBG_Data!$U$2:$U$4000,0))*Settings!$B$25,NA())) | AJ2: =IF(NOT(ISNUMBER($A2)),NA(),IFERROR(1*INDEX(BBG_Data!$X$2:$X$4000,MATCH($A2,BBG_Data!$W$2:$W$4000,0)),NA())) | AK2: =IF(NOT(ISNUMBER($A2)),NA(),IFERROR(1*INDEX(BBG_Data!$Z$2:$Z$4000,MATCH($A2,BBG_Data!$Y$2:$Y$4000,0)),NA()))
A3: =IF(ISNUMBER(BBG_Data!A3),BBG_Data!A3,"") | B3: =IF(AND(ISNUMBER($A3),ISNUMBER(BBG_Data!B3)),BBG_Data!B3,NA()) | C3: =IF(NOT(ISNUMBER($A3)),NA(),IFERROR(1*INDEX(BBG_Data!$D$2:$D$4000,MATCH($A3,BBG_Data!$C$2:$C$4000,0)),NA())) | D3: =IF(NOT(ISNUMBER($A3)),NA(),IFERROR(1*INDEX(BBG_Data!$F$2:$F$4000,MATCH($A3,BBG_Data!$E$2:$E$4000,0)),NA())) | E3: =IF(NOT(ISNUMBER($A3)),NA(),IFERROR(1*INDEX(BBG_Data!$H$2:$H$4000,MATCH($A3,BBG_Data!$G$2:$G$4000,0)),NA())) | F3: =IF(AND(ISNUMBER(B3),ISNUMBER(B2)),IF(B3=B2,"",(B3-B2)*100),"") | G3: =IF(AND(ISNUMBER(C3),ISNUMBER(C2)),IF(C3=C2,"",(C3-C2)*100),"") | H3: =IF(OR(NOT(ISNUMBER($A3)),ROW()-2<Settings!$B$11),NA(),IF(COUNT(OFFSET(F3,1-Settings!$B$11,0,Settings!$B$11,1))<ROUNDUP(Settings!$B$11*Settings!$B$26,0),NA(),STDEV(OFFSET(F3,1-Settings!$B$11,0,Settings!$B$11,1))*SQRT(Settings!$B$13))) | I3: =IF(OR(NOT(ISNUMBER($A3)),ROW()-2<Settings!$B$12),NA(),IF(COUNT(OFFSET(F3,1-Settings!$B$12,0,Settings!$B$12,1))<ROUNDUP(Settings!$B$12*Settings!$B$26,0),NA(),STDEV(OFFSET(F3,1-Settings!$B$12,0,Settings!$B$12,1))*SQRT(Settings!$B$13))) | J3: =IF(OR(NOT(ISNUMBER($A3)),ROW()-2<Settings!$B$11),NA(),IF(COUNT(OFFSET(G3,1-Settings!$B$11,0,Settings!$B$11,1))<ROUNDUP(Settings!$B$11*Settings!$B$26,0),NA(),STDEV(OFFSET(G3,1-Settings!$B$11,0,Settings!$B$11,1))*SQRT(Settings!$B$13))) | K3: =IF(OR(NOT(ISNUMBER($A3)),ROW()-2<Settings!$B$12),NA(),IF(COUNT(OFFSET(G3,1-Settings!$B$12,0,Settings!$B$12,1))<ROUNDUP(Settings!$B$12*Settings!$B$26,0),NA(),STDEV(OFFSET(G3,1-Settings!$B$12,0,Settings!$B$12,1))*SQRT(Settings!$B$13))) | L3: =IF(AND(ISNUMBER(D3),ISNUMBER(H3)),D3-H3,NA()) | M3: =IF(AND(ISNUMBER(E3),ISNUMBER(K3)),E3-K3,NA()) | N3: =IF(NOT(ISNUMBER($A3)),NA(),IF(COUNT(OFFSET(G3,1,0,Settings!$B$12,1))<ROUNDUP(Settings!$B$12*Settings!$B$26,0),NA(),STDEV(OFFSET(G3,1,0,Settings!$B$12,1))*SQRT(Settings!$B$13))) | O3: =IF(AND(ISNUMBER(E3),ISNUMBER(N3)),E3-N3,NA()) | P3: =IF(NOT(ISNUMBER($A3)),NA(),IF(OR($A3<MIN(KW_TP!$A$2:$A$2501),$A3>MAX(KW_TP!$A$2:$A$2501)),NA(),INDEX(KW_TP!$C$2:$C$2501,MATCH($A3,KW_TP!$A$2:$A$2501,1)))) | Q3: =IF(NOT(ISNUMBER($A3)),NA(),IFERROR(1*INDEX(BBG_Data!$J$2:$J$4000,MATCH($A3,BBG_Data!$I$2:$I$4000,0)),NA())) | R3: =IF(NOT(ISNUMBER($A3)),NA(),IFERROR(1*INDEX(BBG_Data!$L$2:$L$4000,MATCH($A3,BBG_Data!$K$2:$K$4000,0)),NA())) | S3: =IF(AND(ISNUMBER(B3),ISNUMBER(Q3),ISNUMBER(R3)),(B3-Q3-R3)*100,NA()) | T3: =IF(AND(ISNUMBER(B3),Settings!$B$17>0),IF(ISNUMBER(INDEX($B:$B,Settings!$B$17)),(B3-INDEX($B:$B,Settings!$B$17))*100,NA()),NA()) | U3: =IF(AND(ISNUMBER(Q3),Settings!$B$17>0),IF(ISNUMBER(INDEX($Q:$Q,Settings!$B$17)),(Q3-INDEX($Q:$Q,Settings!$B$17))*100,NA()),NA()) | V3: =IF(AND(ISNUMBER(R3),Settings!$B$17>0),IF(ISNUMBER(INDEX($R:$R,Settings!$B$17)),(R3-INDEX($R:$R,Settings!$B$17))*100,NA()),NA()) | W3: =IF(AND(ISNUMBER(P3),Settings!$B$17>0),IF(ISNUMBER(INDEX($P:$P,Settings!$B$17)),P3-INDEX($P:$P,Settings!$B$17),NA()),NA()) | X3: =IF(NOT(ISNUMBER($A3)),NA(),IF(OR($A3<MIN(DKW_10Y!$A$2:$A$2918),$A3>MAX(DKW_10Y!$A$2:$A$2918),Settings!$B$16<MIN(DKW_10Y!$A$2:$A$2918)),NA(),(INDEX(DKW_10Y!$B$2:$B$2918,MATCH($A3,DKW_10Y!$A$2:$A$2918,1))-INDEX(DKW_10Y!$B$2:$B$2918,MATCH(Settings!$B$16,DKW_10Y!$A$2:$A$2918,1)))*100)) | Y3: =IF(NOT(ISNUMBER($A3)),NA(),IF(OR($A3<MIN(DKW_10Y!$A$2:$A$2918),$A3>MAX(DKW_10Y!$A$2:$A$2918),Settings!$B$16<MIN(DKW_10Y!$A$2:$A$2918)),NA(),(INDEX(DKW_10Y!$C$2:$C$2918,MATCH($A3,DKW_10Y!$A$2:$A$2918,1))-INDEX(DKW_10Y!$C$2:$C$2918,MATCH(Settings!$B$16,DKW_10Y!$A$2:$A$2918,1)))*100)) | Z3: =IF(NOT(ISNUMBER($A3)),NA(),IF(OR($A3<MIN(DKW_10Y!$A$2:$A$2918),$A3>MAX(DKW_10Y!$A$2:$A$2918),Settings!$B$16<MIN(DKW_10Y!$A$2:$A$2918)),NA(),(INDEX(DKW_10Y!$D$2:$D$2918,MATCH($A3,DKW_10Y!$A$2:$A$2918,1))-INDEX(DKW_10Y!$D$2:$D$2918,MATCH(Settings!$B$16,DKW_10Y!$A$2:$A$2918,1)))*100)) | AA3: =IF(NOT(ISNUMBER($A3)),NA(),IF(OR($A3<MIN(DKW_10Y!$A$2:$A$2918),$A3>MAX(DKW_10Y!$A$2:$A$2918),Settings!$B$16<MIN(DKW_10Y!$A$2:$A$2918)),NA(),(INDEX(DKW_10Y!$E$2:$E$2918,MATCH($A3,DKW_10Y!$A$2:$A$2918,1))-INDEX(DKW_10Y!$E$2:$E$2918,MATCH(Settings!$B$16,DKW_10Y!$A$2:$A$2918,1)))*100)) | AB3: =IF(NOT(ISNUMBER($A3)),NA(),IF(OR($A3<MIN(DKW_10Y!$A$2:$A$2918),$A3>MAX(DKW_10Y!$A$2:$A$2918),Settings!$B$16<MIN(DKW_10Y!$A$2:$A$2918)),NA(),(INDEX(DKW_10Y!$H$2:$H$2918,MATCH($A3,DKW_10Y!$A$2:$A$2918,1))-INDEX(DKW_10Y!$H$2:$H$2918,MATCH(Settings!$B$16,DKW_10Y!$A$2:$A$2918,1)))*100)) | AC3: =IF(NOT(ISNUMBER($A3)),NA(),IFERROR(1*INDEX(BBG_Data!$N$2:$N$4000,MATCH($A3,BBG_Data!$M$2:$M$4000,0)),NA())) | AD3: =IF(NOT(ISNUMBER($A3)),NA(),IFERROR(1*INDEX(BBG_Data!$P$2:$P$4000,MATCH($A3,BBG_Data!$O$2:$O$4000,0)),NA())) | AE3: =IF(NOT(ISNUMBER($A3)),NA(),IFERROR(1*INDEX(BBG_Data!$R$2:$R$4000,MATCH($A3,BBG_Data!$Q$2:$Q$4000,0)),NA())) | AF3: =IF(AND(ISNUMBER(B3),ISNUMBER(AC3)),(B3-AC3)*100,NA()) | AG3: =IF(AND(ISNUMBER(AE3),ISNUMBER(AD3)),(AE3-AD3)*100,NA()) | AH3: =IF(NOT(ISNUMBER($A3)),NA(),IFERROR(INDEX(BBG_Data!$T$2:$T$4000,MATCH($A3,BBG_Data!$S$2:$S$4000,0))*Settings!$B$25,NA())) | AI3: =IF(NOT(ISNUMBER($A3)),NA(),IFERROR(INDEX(BBG_Data!$V$2:$V$4000,MATCH($A3,BBG_Data!$U$2:$U$4000,0))*Settings!$B$25,NA())) | AJ3: =IF(NOT(ISNUMBER($A3)),NA(),IFERROR(1*INDEX(BBG_Data!$X$2:$X$4000,MATCH($A3,BBG_Data!$W$2:$W$4000,0)),NA())) | AK3: =IF(NOT(ISNUMBER($A3)),NA(),IFERROR(1*INDEX(BBG_Data!$Z$2:$Z$4000,MATCH($A3,BBG_Data!$Y$2:$Y$4000,0)),NA()))
A4: =IF(ISNUMBER(BBG_Data!A4),BBG_Data!A4,"") | B4: =IF(AND(ISNUMBER($A4),ISNUMBER(BBG_Data!B4)),BBG_Data!B4,NA()) | C4: =IF(NOT(ISNUMBER($A4)),NA(),IFERROR(1*INDEX(BBG_Data!$D$2:$D$4000,MATCH($A4,BBG_Data!$C$2:$C$4000,0)),NA())) | D4: =IF(NOT(ISNUMBER($A4)),NA(),IFERROR(1*INDEX(BBG_Data!$F$2:$F$4000,MATCH($A4,BBG_Data!$E$2:$E$4000,0)),NA())) | E4: =IF(NOT(ISNUMBER($A4)),NA(),IFERROR(1*INDEX(BBG_Data!$H$2:$H$4000,MATCH($A4,BBG_Data!$G$2:$G$4000,0)),NA())) | F4: =IF(AND(ISNUMBER(B4),ISNUMBER(B3)),IF(B4=B3,"",(B4-B3)*100),"") | G4: =IF(AND(ISNUMBER(C4),ISNUMBER(C3)),IF(C4=C3,"",(C4-C3)*100),"") | H4: =IF(OR(NOT(ISNUMBER($A4)),ROW()-2<Settings!$B$11),NA(),IF(COUNT(OFFSET(F4,1-Settings!$B$11,0,Settings!$B$11,1))<ROUNDUP(Settings!$B$11*Settings!$B$26,0),NA(),STDEV(OFFSET(F4,1-Settings!$B$11,0,Settings!$B$11,1))*SQRT(Settings!$B$13))) | I4: =IF(OR(NOT(ISNUMBER($A4)),ROW()-2<Settings!$B$12),NA(),IF(COUNT(OFFSET(F4,1-Settings!$B$12,0,Settings!$B$12,1))<ROUNDUP(Settings!$B$12*Settings!$B$26,0),NA(),STDEV(OFFSET(F4,1-Settings!$B$12,0,Settings!$B$12,1))*SQRT(Settings!$B$13))) | J4: =IF(OR(NOT(ISNUMBER($A4)),ROW()-2<Settings!$B$11),NA(),IF(COUNT(OFFSET(G4,1-Settings!$B$11,0,Settings!$B$11,1))<ROUNDUP(Settings!$B$11*Settings!$B$26,0),NA(),STDEV(OFFSET(G4,1-Settings!$B$11,0,Settings!$B$11,1))*SQRT(Settings!$B$13))) | K4: =IF(OR(NOT(ISNUMBER($A4)),ROW()-2<Settings!$B$12),NA(),IF(COUNT(OFFSET(G4,1-Settings!$B$12,0,Settings!$B$12,1))<ROUNDUP(Settings!$B$12*Settings!$B$26,0),NA(),STDEV(OFFSET(G4,1-Settings!$B$12,0,Settings!$B$12,1))*SQRT(Settings!$B$13))) | L4: =IF(AND(ISNUMBER(D4),ISNUMBER(H4)),D4-H4,NA()) | M4: =IF(AND(ISNUMBER(E4),ISNUMBER(K4)),E4-K4,NA()) | N4: =IF(NOT(ISNUMBER($A4)),NA(),IF(COUNT(OFFSET(G4,1,0,Settings!$B$12,1))<ROUNDUP(Settings!$B$12*Settings!$B$26,0),NA(),STDEV(OFFSET(G4,1,0,Settings!$B$12,1))*SQRT(Settings!$B$13))) | O4: =IF(AND(ISNUMBER(E4),ISNUMBER(N4)),E4-N4,NA()) | P4: =IF(NOT(ISNUMBER($A4)),NA(),IF(OR($A4<MIN(KW_TP!$A$2:$A$2501),$A4>MAX(KW_TP!$A$2:$A$2501)),NA(),INDEX(KW_TP!$C$2:$C$2501,MATCH($A4,KW_TP!$A$2:$A$2501,1)))) | Q4: =IF(NOT(ISNUMBER($A4)),NA(),IFERROR(1*INDEX(BBG_Data!$J$2:$J$4000,MATCH($A4,BBG_Data!$I$2:$I$4000,0)),NA())) | R4: =IF(NOT(ISNUMBER($A4)),NA(),IFERROR(1*INDEX(BBG_Data!$L$2:$L$4000,MATCH($A4,BBG_Data!$K$2:$K$4000,0)),NA())) | S4: =IF(AND(ISNUMBER(B4),ISNUMBER(Q4),ISNUMBER(R4)),(B4-Q4-R4)*100,NA()) | T4: =IF(AND(ISNUMBER(B4),Settings!$B$17>0),IF(ISNUMBER(INDEX($B:$B,Settings!$B$17)),(B4-INDEX($B:$B,Settings!$B$17))*100,NA()),NA()) | U4: =IF(AND(ISNUMBER(Q4),Settings!$B$17>0),IF(ISNUMBER(INDEX($Q:$Q,Settings!$B$17)),(Q4-INDEX($Q:$Q,Settings!$B$17))*100,NA()),NA()) | V4: =IF(AND(ISNUMBER(R4),Settings!$B$17>0),IF(ISNUMBER(INDEX($R:$R,Settings!$B$17)),(R4-INDEX($R:$R,Settings!$B$17))*100,NA()),NA()) | W4: =IF(AND(ISNUMBER(P4),Settings!$B$17>0),IF(ISNUMBER(INDEX($P:$P,Settings!$B$17)),P4-INDEX($P:$P,Settings!$B$17),NA()),NA()) | X4: =IF(NOT(ISNUMBER($A4)),NA(),IF(OR($A4<MIN(DKW_10Y!$A$2:$A$2918),$A4>MAX(DKW_10Y!$A$2:$A$2918),Settings!$B$16<MIN(DKW_10Y!$A$2:$A$2918)),NA(),(INDEX(DKW_10Y!$B$2:$B$2918,MATCH($A4,DKW_10Y!$A$2:$A$2918,1))-INDEX(DKW_10Y!$B$2:$B$2918,MATCH(Settings!$B$16,DKW_10Y!$A$2:$A$2918,1)))*100)) | Y4: =IF(NOT(ISNUMBER($A4)),NA(),IF(OR($A4<MIN(DKW_10Y!$A$2:$A$2918),$A4>MAX(DKW_10Y!$A$2:$A$2918),Settings!$B$16<MIN(DKW_10Y!$A$2:$A$2918)),NA(),(INDEX(DKW_10Y!$C$2:$C$2918,MATCH($A4,DKW_10Y!$A$2:$A$2918,1))-INDEX(DKW_10Y!$C$2:$C$2918,MATCH(Settings!$B$16,DKW_10Y!$A$2:$A$2918,1)))*100)) | Z4: =IF(NOT(ISNUMBER($A4)),NA(),IF(OR($A4<MIN(DKW_10Y!$A$2:$A$2918),$A4>MAX(DKW_10Y!$A$2:$A$2918),Settings!$B$16<MIN(DKW_10Y!$A$2:$A$2918)),NA(),(INDEX(DKW_10Y!$D$2:$D$2918,MATCH($A4,DKW_10Y!$A$2:$A$2918,1))-INDEX(DKW_10Y!$D$2:$D$2918,MATCH(Settings!$B$16,DKW_10Y!$A$2:$A$2918,1)))*100)) | AA4: =IF(NOT(ISNUMBER($A4)),NA(),IF(OR($A4<MIN(DKW_10Y!$A$2:$A$2918),$A4>MAX(DKW_10Y!$A$2:$A$2918),Settings!$B$16<MIN(DKW_10Y!$A$2:$A$2918)),NA(),(INDEX(DKW_10Y!$E$2:$E$2918,MATCH($A4,DKW_10Y!$A$2:$A$2918,1))-INDEX(DKW_10Y!$E$2:$E$2918,MATCH(Settings!$B$16,DKW_10Y!$A$2:$A$2918,1)))*100)) | AB4: =IF(NOT(ISNUMBER($A4)),NA(),IF(OR($A4<MIN(DKW_10Y!$A$2:$A$2918),$A4>MAX(DKW_10Y!$A$2:$A$2918),Settings!$B$16<MIN(DKW_10Y!$A$2:$A$2918)),NA(),(INDEX(DKW_10Y!$H$2:$H$2918,MATCH($A4,DKW_10Y!$A$2:$A$2918,1))-INDEX(DKW_10Y!$H$2:$H$2918,MATCH(Settings!$B$16,DKW_10Y!$A$2:$A$2918,1)))*100)) | AC4: =IF(NOT(ISNUMBER($A4)),NA(),IFERROR(1*INDEX(BBG_Data!$N$2:$N$4000,MATCH($A4,BBG_Data!$M$2:$M$4000,0)),NA())) | AD4: =IF(NOT(ISNUMBER($A4)),NA(),IFERROR(1*INDEX(BBG_Data!$P$2:$P$4000,MATCH($A4,BBG_Data!$O$2:$O$4000,0)),NA())) | AE4: =IF(NOT(ISNUMBER($A4)),NA(),IFERROR(1*INDEX(BBG_Data!$R$2:$R$4000,MATCH($A4,BBG_Data!$Q$2:$Q$4000,0)),NA())) | AF4: =IF(AND(ISNUMBER(B4),ISNUMBER(AC4)),(B4-AC4)*100,NA()) | AG4: =IF(AND(ISNUMBER(AE4),ISNUMBER(AD4)),(AE4-AD4)*100,NA()) | AH4: =IF(NOT(ISNUMBER($A4)),NA(),IFERROR(INDEX(BBG_Data!$T$2:$T$4000,MATCH($A4,BBG_Data!$S$2:$S$4000,0))*Settings!$B$25,NA())) | AI4: =IF(NOT(ISNUMBER($A4)),NA(),IFERROR(INDEX(BBG_Data!$V$2:$V$4000,MATCH($A4,BBG_Data!$U$2:$U$4000,0))*Settings!$B$25,NA())) | AJ4: =IF(NOT(ISNUMBER($A4)),NA(),IFERROR(1*INDEX(BBG_Data!$X$2:$X$4000,MATCH($A4,BBG_Data!$W$2:$W$4000,0)),NA())) | AK4: =IF(NOT(ISNUMBER($A4)),NA(),IFERROR(1*INDEX(BBG_Data!$Z$2:$Z$4000,MATCH($A4,BBG_Data!$Y$2:$Y$4000,0)),NA()))
A5: =IF(ISNUMBER(BBG_Data!A5),BBG_Data!A5,"") | B5: =IF(AND(ISNUMBER($A5),ISNUMBER(BBG_Data!B5)),BBG_Data!B5,NA()) | C5: =IF(NOT(ISNUMBER($A5)),NA(),IFERROR(1*INDEX(BBG_Data!$D$2:$D$4000,MATCH($A5,BBG_Data!$C$2:$C$4000,0)),NA())) | D5: =IF(NOT(ISNUMBER($A5)),NA(),IFERROR(1*INDEX(BBG_Data!$F$2:$F$4000,MATCH($A5,BBG_Data!$E$2:$E$4000,0)),NA())) | E5: =IF(NOT(ISNUMBER($A5)),NA(),IFERROR(1*INDEX(BBG_Data!$H$2:$H$4000,MATCH($A5,BBG_Data!$G$2:$G$4000,0)),NA())) | F5: =IF(AND(ISNUMBER(B5),ISNUMBER(B4)),IF(B5=B4,"",(B5-B4)*100),"") | G5: =IF(AND(ISNUMBER(C5),ISNUMBER(C4)),IF(C5=C4,"",(C5-C4)*100),"") | H5: =IF(OR(NOT(ISNUMBER($A5)),ROW()-2<Settings!$B$11),NA(),IF(COUNT(OFFSET(F5,1-Settings!$B$11,0,Settings!$B$11,1))<ROUNDUP(Settings!$B$11*Settings!$B$26,0),NA(),STDEV(OFFSET(F5,1-Settings!$B$11,0,Settings!$B$11,1))*SQRT(Settings!$B$13))) | I5: =IF(OR(NOT(ISNUMBER($A5)),ROW()-2<Settings!$B$12),NA(),IF(COUNT(OFFSET(F5,1-Settings!$B$12,0,Settings!$B$12,1))<ROUNDUP(Settings!$B$12*Settings!$B$26,0),NA(),STDEV(OFFSET(F5,1-Settings!$B$12,0,Settings!$B$12,1))*SQRT(Settings!$B$13))) | J5: =IF(OR(NOT(ISNUMBER($A5)),ROW()-2<Settings!$B$11),NA(),IF(COUNT(OFFSET(G5,1-Settings!$B$11,0,Settings!$B$11,1))<ROUNDUP(Settings!$B$11*Settings!$B$26,0),NA(),STDEV(OFFSET(G5,1-Settings!$B$11,0,Settings!$B$11,1))*SQRT(Settings!$B$13))) | K5: =IF(OR(NOT(ISNUMBER($A5)),ROW()-2<Settings!$B$12),NA(),IF(COUNT(OFFSET(G5,1-Settings!$B$12,0,Settings!$B$12,1))<ROUNDUP(Settings!$B$12*Settings!$B$26,0),NA(),STDEV(OFFSET(G5,1-Settings!$B$12,0,Settings!$B$12,1))*SQRT(Settings!$B$13))) | L5: =IF(AND(ISNUMBER(D5),ISNUMBER(H5)),D5-H5,NA()) | M5: =IF(AND(ISNUMBER(E5),ISNUMBER(K5)),E5-K5,NA()) | N5: =IF(NOT(ISNUMBER($A5)),NA(),IF(COUNT(OFFSET(G5,1,0,Settings!$B$12,1))<ROUNDUP(Settings!$B$12*Settings!$B$26,0),NA(),STDEV(OFFSET(G5,1,0,Settings!$B$12,1))*SQRT(Settings!$B$13))) | O5: =IF(AND(ISNUMBER(E5),ISNUMBER(N5)),E5-N5,NA()) | P5: =IF(NOT(ISNUMBER($A5)),NA(),IF(OR($A5<MIN(KW_TP!$A$2:$A$2501),$A5>MAX(KW_TP!$A$2:$A$2501)),NA(),INDEX(KW_TP!$C$2:$C$2501,MATCH($A5,KW_TP!$A$2:$A$2501,1)))) | Q5: =IF(NOT(ISNUMBER($A5)),NA(),IFERROR(1*INDEX(BBG_Data!$J$2:$J$4000,MATCH($A5,BBG_Data!$I$2:$I$4000,0)),NA())) | R5: =IF(NOT(ISNUMBER($A5)),NA(),IFERROR(1*INDEX(BBG_Data!$L$2:$L$4000,MATCH($A5,BBG_Data!$K$2:$K$4000,0)),NA())) | S5: =IF(AND(ISNUMBER(B5),ISNUMBER(Q5),ISNUMBER(R5)),(B5-Q5-R5)*100,NA()) | T5: =IF(AND(ISNUMBER(B5),Settings!$B$17>0),IF(ISNUMBER(INDEX($B:$B,Settings!$B$17)),(B5-INDEX($B:$B,Settings!$B$17))*100,NA()),NA()) | U5: =IF(AND(ISNUMBER(Q5),Settings!$B$17>0),IF(ISNUMBER(INDEX($Q:$Q,Settings!$B$17)),(Q5-INDEX($Q:$Q,Settings!$B$17))*100,NA()),NA()) | V5: =IF(AND(ISNUMBER(R5),Settings!$B$17>0),IF(ISNUMBER(INDEX($R:$R,Settings!$B$17)),(R5-INDEX($R:$R,Settings!$B$17))*100,NA()),NA()) | W5: =IF(AND(ISNUMBER(P5),Settings!$B$17>0),IF(ISNUMBER(INDEX($P:$P,Settings!$B$17)),P5-INDEX($P:$P,Settings!$B$17),NA()),NA()) | X5: =IF(NOT(ISNUMBER($A5)),NA(),IF(OR($A5<MIN(DKW_10Y!$A$2:$A$2918),$A5>MAX(DKW_10Y!$A$2:$A$2918),Settings!$B$16<MIN(DKW_10Y!$A$2:$A$2918)),NA(),(INDEX(DKW_10Y!$B$2:$B$2918,MATCH($A5,DKW_10Y!$A$2:$A$2918,1))-INDEX(DKW_10Y!$B$2:$B$2918,MATCH(Settings!$B$16,DKW_10Y!$A$2:$A$2918,1)))*100)) | Y5: =IF(NOT(ISNUMBER($A5)),NA(),IF(OR($A5<MIN(DKW_10Y!$A$2:$A$2918),$A5>MAX(DKW_10Y!$A$2:$A$2918),Settings!$B$16<MIN(DKW_10Y!$A$2:$A$2918)),NA(),(INDEX(DKW_10Y!$C$2:$C$2918,MATCH($A5,DKW_10Y!$A$2:$A$2918,1))-INDEX(DKW_10Y!$C$2:$C$2918,MATCH(Settings!$B$16,DKW_10Y!$A$2:$A$2918,1)))*100)) | Z5: =IF(NOT(ISNUMBER($A5)),NA(),IF(OR($A5<MIN(DKW_10Y!$A$2:$A$2918),$A5>MAX(DKW_10Y!$A$2:$A$2918),Settings!$B$16<MIN(DKW_10Y!$A$2:$A$2918)),NA(),(INDEX(DKW_10Y!$D$2:$D$2918,MATCH($A5,DKW_10Y!$A$2:$A$2918,1))-INDEX(DKW_10Y!$D$2:$D$2918,MATCH(Settings!$B$16,DKW_10Y!$A$2:$A$2918,1)))*100)) | AA5: =IF(NOT(ISNUMBER($A5)),NA(),IF(OR($A5<MIN(DKW_10Y!$A$2:$A$2918),$A5>MAX(DKW_10Y!$A$2:$A$2918),Settings!$B$16<MIN(DKW_10Y!$A$2:$A$2918)),NA(),(INDEX(DKW_10Y!$E$2:$E$2918,MATCH($A5,DKW_10Y!$A$2:$A$2918,1))-INDEX(DKW_10Y!$E$2:$E$2918,MATCH(Settings!$B$16,DKW_10Y!$A$2:$A$2918,1)))*100)) | AB5: =IF(NOT(ISNUMBER($A5)),NA(),IF(OR($A5<MIN(DKW_10Y!$A$2:$A$2918),$A5>MAX(DKW_10Y!$A$2:$A$2918),Settings!$B$16<MIN(DKW_10Y!$A$2:$A$2918)),NA(),(INDEX(DKW_10Y!$H$2:$H$2918,MATCH($A5,DKW_10Y!$A$2:$A$2918,1))-INDEX(DKW_10Y!$H$2:$H$2918,MATCH(Settings!$B$16,DKW_10Y!$A$2:$A$2918,1)))*100)) | AC5: =IF(NOT(ISNUMBER($A5)),NA(),IFERROR(1*INDEX(BBG_Data!$N$2:$N$4000,MATCH($A5,BBG_Data!$M$2:$M$4000,0)),NA())) | AD5: =IF(NOT(ISNUMBER($A5)),NA(),IFERROR(1*INDEX(BBG_Data!$P$2:$P$4000,MATCH($A5,BBG_Data!$O$2:$O$4000,0)),NA())) | AE5: =IF(NOT(ISNUMBER($A5)),NA(),IFERROR(1*INDEX(BBG_Data!$R$2:$R$4000,MATCH($A5,BBG_Data!$Q$2:$Q$4000,0)),NA())) | AF5: =IF(AND(ISNUMBER(B5),ISNUMBER(AC5)),(B5-AC5)*100,NA()) | AG5: =IF(AND(ISNUMBER(AE5),ISNUMBER(AD5)),(AE5-AD5)*100,NA()) | AH5: =IF(NOT(ISNUMBER($A5)),NA(),IFERROR(INDEX(BBG_Data!$T$2:$T$4000,MATCH($A5,BBG_Data!$S$2:$S$4000,0))*Settings!$B$25,NA())) | AI5: =IF(NOT(ISNUMBER($A5)),NA(),IFERROR(INDEX(BBG_Data!$V$2:$V$4000,MATCH($A5,BBG_Data!$U$2:$U$4000,0))*Settings!$B$25,NA())) | AJ5: =IF(NOT(ISNUMBER($A5)),NA(),IFERROR(1*INDEX(BBG_Data!$X$2:$X$4000,MATCH($A5,BBG_Data!$W$2:$W$4000,0)),NA())) | AK5: =IF(NOT(ISNUMBER($A5)),NA(),IFERROR(1*INDEX(BBG_Data!$Z$2:$Z$4000,MATCH($A5,BBG_Data!$Y$2:$Y$4000,0)),NA()))
A6: =IF(ISNUMBER(BBG_Data!A6),BBG_Data!A6,"") | B6: =IF(AND(ISNUMBER($A6),ISNUMBER(BBG_Data!B6)),BBG_Data!B6,NA()) | C6: =IF(NOT(ISNUMBER($A6)),NA(),IFERROR(1*INDEX(BBG_Data!$D$2:$D$4000,MATCH($A6,BBG_Data!$C$2:$C$4000,0)),NA())) | D6: =IF(NOT(ISNUMBER($A6)),NA(),IFERROR(1*INDEX(BBG_Data!$F$2:$F$4000,MATCH($A6,BBG_Data!$E$2:$E$4000,0)),NA())) | E6: =IF(NOT(ISNUMBER($A6)),NA(),IFERROR(1*INDEX(BBG_Data!$H$2:$H$4000,MATCH($A6,BBG_Data!$G$2:$G$4000,0)),NA())) | F6: =IF(AND(ISNUMBER(B6),ISNUMBER(B5)),IF(B6=B5,"",(B6-B5)*100),"") | G6: =IF(AND(ISNUMBER(C6),ISNUMBER(C5)),IF(C6=C5,"",(C6-C5)*100),"") | H6: =IF(OR(NOT(ISNUMBER($A6)),ROW()-2<Settings!$B$11),NA(),IF(COUNT(OFFSET(F6,1-Settings!$B$11,0,Settings!$B$11,1))<ROUNDUP(Settings!$B$11*Settings!$B$26,0),NA(),STDEV(OFFSET(F6,1-Settings!$B$11,0,Settings!$B$11,1))*SQRT(Settings!$B$13))) | I6: =IF(OR(NOT(ISNUMBER($A6)),ROW()-2<Settings!$B$12),NA(),IF(COUNT(OFFSET(F6,1-Settings!$B$12,0,Settings!$B$12,1))<ROUNDUP(Settings!$B$12*Settings!$B$26,0),NA(),STDEV(OFFSET(F6,1-Settings!$B$12,0,Settings!$B$12,1))*SQRT(Settings!$B$13))) | J6: =IF(OR(NOT(ISNUMBER($A6)),ROW()-2<Settings!$B$11),NA(),IF(COUNT(OFFSET(G6,1-Settings!$B$11,0,Settings!$B$11,1))<ROUNDUP(Settings!$B$11*Settings!$B$26,0),NA(),STDEV(OFFSET(G6,1-Settings!$B$11,0,Settings!$B$11,1))*SQRT(Settings!$B$13))) | K6: =IF(OR(NOT(ISNUMBER($A6)),ROW()-2<Settings!$B$12),NA(),IF(COUNT(OFFSET(G6,1-Settings!$B$12,0,Settings!$B$12,1))<ROUNDUP(Settings!$B$12*Settings!$B$26,0),NA(),STDEV(OFFSET(G6,1-Settings!$B$12,0,Settings!$B$12,1))*SQRT(Settings!$B$13))) | L6: =IF(AND(ISNUMBER(D6),ISNUMBER(H6)),D6-H6,NA()) | M6: =IF(AND(ISNUMBER(E6),ISNUMBER(K6)),E6-K6,NA()) | N6: =IF(NOT(ISNUMBER($A6)),NA(),IF(COUNT(OFFSET(G6,1,0,Settings!$B$12,1))<ROUNDUP(Settings!$B$12*Settings!$B$26,0),NA(),STDEV(OFFSET(G6,1,0,Settings!$B$12,1))*SQRT(Settings!$B$13))) | O6: =IF(AND(ISNUMBER(E6),ISNUMBER(N6)),E6-N6,NA()) | P6: =IF(NOT(ISNUMBER($A6)),NA(),IF(OR($A6<MIN(KW_TP!$A$2:$A$2501),$A6>MAX(KW_TP!$A$2:$A$2501)),NA(),INDEX(KW_TP!$C$2:$C$2501,MATCH($A6,KW_TP!$A$2:$A$2501,1)))) | Q6: =IF(NOT(ISNUMBER($A6)),NA(),IFERROR(1*INDEX(BBG_Data!$J$2:$J$4000,MATCH($A6,BBG_Data!$I$2:$I$4000,0)),NA())) | R6: =IF(NOT(ISNUMBER($A6)),NA(),IFERROR(1*INDEX(BBG_Data!$L$2:$L$4000,MATCH($A6,BBG_Data!$K$2:$K$4000,0)),NA())) | S6: =IF(AND(ISNUMBER(B6),ISNUMBER(Q6),ISNUMBER(R6)),(B6-Q6-R6)*100,NA()) | T6: =IF(AND(ISNUMBER(B6),Settings!$B$17>0),IF(ISNUMBER(INDEX($B:$B,Settings!$B$17)),(B6-INDEX($B:$B,Settings!$B$17))*100,NA()),NA()) | U6: =IF(AND(ISNUMBER(Q6),Settings!$B$17>0),IF(ISNUMBER(INDEX($Q:$Q,Settings!$B$17)),(Q6-INDEX($Q:$Q,Settings!$B$17))*100,NA()),NA()) | V6: =IF(AND(ISNUMBER(R6),Settings!$B$17>0),IF(ISNUMBER(INDEX($R:$R,Settings!$B$17)),(R6-INDEX($R:$R,Settings!$B$17))*100,NA()),NA()) | W6: =IF(AND(ISNUMBER(P6),Settings!$B$17>0),IF(ISNUMBER(INDEX($P:$P,Settings!$B$17)),P6-INDEX($P:$P,Settings!$B$17),NA()),NA()) | X6: =IF(NOT(ISNUMBER($A6)),NA(),IF(OR($A6<MIN(DKW_10Y!$A$2:$A$2918),$A6>MAX(DKW_10Y!$A$2:$A$2918),Settings!$B$16<MIN(DKW_10Y!$A$2:$A$2918)),NA(),(INDEX(DKW_10Y!$B$2:$B$2918,MATCH($A6,DKW_10Y!$A$2:$A$2918,1))-INDEX(DKW_10Y!$B$2:$B$2918,MATCH(Settings!$B$16,DKW_10Y!$A$2:$A$2918,1)))*100)) | Y6: =IF(NOT(ISNUMBER($A6)),NA(),IF(OR($A6<MIN(DKW_10Y!$A$2:$A$2918),$A6>MAX(DKW_10Y!$A$2:$A$2918),Settings!$B$16<MIN(DKW_10Y!$A$2:$A$2918)),NA(),(INDEX(DKW_10Y!$C$2:$C$2918,MATCH($A6,DKW_10Y!$A$2:$A$2918,1))-INDEX(DKW_10Y!$C$2:$C$2918,MATCH(Settings!$B$16,DKW_10Y!$A$2:$A$2918,1)))*100)) | Z6: =IF(NOT(ISNUMBER($A6)),NA(),IF(OR($A6<MIN(DKW_10Y!$A$2:$A$2918),$A6>MAX(DKW_10Y!$A$2:$A$2918),Settings!$B$16<MIN(DKW_10Y!$A$2:$A$2918)),NA(),(INDEX(DKW_10Y!$D$2:$D$2918,MATCH($A6,DKW_10Y!$A$2:$A$2918,1))-INDEX(DKW_10Y!$D$2:$D$2918,MATCH(Settings!$B$16,DKW_10Y!$A$2:$A$2918,1)))*100)) | AA6: =IF(NOT(ISNUMBER($A6)),NA(),IF(OR($A6<MIN(DKW_10Y!$A$2:$A$2918),$A6>MAX(DKW_10Y!$A$2:$A$2918),Settings!$B$16<MIN(DKW_10Y!$A$2:$A$2918)),NA(),(INDEX(DKW_10Y!$E$2:$E$2918,MATCH($A6,DKW_10Y!$A$2:$A$2918,1))-INDEX(DKW_10Y!$E$2:$E$2918,MATCH(Settings!$B$16,DKW_10Y!$A$2:$A$2918,1)))*100)) | AB6: =IF(NOT(ISNUMBER($A6)),NA(),IF(OR($A6<MIN(DKW_10Y!$A$2:$A$2918),$A6>MAX(DKW_10Y!$A$2:$A$2918),Settings!$B$16<MIN(DKW_10Y!$A$2:$A$2918)),NA(),(INDEX(DKW_10Y!$H$2:$H$2918,MATCH($A6,DKW_10Y!$A$2:$A$2918,1))-INDEX(DKW_10Y!$H$2:$H$2918,MATCH(Settings!$B$16,DKW_10Y!$A$2:$A$2918,1)))*100)) | AC6: =IF(NOT(ISNUMBER($A6)),NA(),IFERROR(1*INDEX(BBG_Data!$N$2:$N$4000,MATCH($A6,BBG_Data!$M$2:$M$4000,0)),NA())) | AD6: =IF(NOT(ISNUMBER($A6)),NA(),IFERROR(1*INDEX(BBG_Data!$P$2:$P$4000,MATCH($A6,BBG_Data!$O$2:$O$4000,0)),NA())) | AE6: =IF(NOT(ISNUMBER($A6)),NA(),IFERROR(1*INDEX(BBG_Data!$R$2:$R$4000,MATCH($A6,BBG_Data!$Q$2:$Q$4000,0)),NA())) | AF6: =IF(AND(ISNUMBER(B6),ISNUMBER(AC6)),(B6-AC6)*100,NA()) | AG6: =IF(AND(ISNUMBER(AE6),ISNUMBER(AD6)),(AE6-AD6)*100,NA()) | AH6: =IF(NOT(ISNUMBER($A6)),NA(),IFERROR(INDEX(BBG_Data!$T$2:$T$4000,MATCH($A6,BBG_Data!$S$2:$S$4000,0))*Settings!$B$25,NA())) | AI6: =IF(NOT(ISNUMBER($A6)),NA(),IFERROR(INDEX(BBG_Data!$V$2:$V$4000,MATCH($A6,BBG_Data!$U$2:$U$4000,0))*Settings!$B$25,NA())) | AJ6: =IF(NOT(ISNUMBER($A6)),NA(),IFERROR(1*INDEX(BBG_Data!$X$2:$X$4000,MATCH($A6,BBG_Data!$W$2:$W$4000,0)),NA())) | AK6: =IF(NOT(ISNUMBER($A6)),NA(),IFERROR(1*INDEX(BBG_Data!$Z$2:$Z$4000,MATCH($A6,BBG_Data!$Y$2:$Y$4000,0)),NA()))
A7: =IF(ISNUMBER(BBG_Data!A7),BBG_Data!A7,"") | B7: =IF(AND(ISNUMBER($A7),ISNUMBER(BBG_Data!B7)),BBG_Data!B7,NA()) | C7: =IF(NOT(ISNUMBER($A7)),NA(),IFERROR(1*INDEX(BBG_Data!$D$2:$D$4000,MATCH($A7,BBG_Data!$C$2:$C$4000,0)),NA())) | D7: =IF(NOT(ISNUMBER($A7)),NA(),IFERROR(1*INDEX(BBG_Data!$F$2:$F$4000,MATCH($A7,BBG_Data!$E$2:$E$4000,0)),NA())) | E7: =IF(NOT(ISNUMBER($A7)),NA(),IFERROR(1*INDEX(BBG_Data!$H$2:$H$4000,MATCH($A7,BBG_Data!$G$2:$G$4000,0)),NA())) | F7: =IF(AND(ISNUMBER(B7),ISNUMBER(B6)),IF(B7=B6,"",(B7-B6)*100),"") | G7: =IF(AND(ISNUMBER(C7),ISNUMBER(C6)),IF(C7=C6,"",(C7-C6)*100),"") | H7: =IF(OR(NOT(ISNUMBER($A7)),ROW()-2<Settings!$B$11),NA(),IF(COUNT(OFFSET(F7,1-Settings!$B$11,0,Settings!$B$11,1))<ROUNDUP(Settings!$B$11*Settings!$B$26,0),NA(),STDEV(OFFSET(F7,1-Settings!$B$11,0,Settings!$B$11,1))*SQRT(Settings!$B$13))) | I7: =IF(OR(NOT(ISNUMBER($A7)),ROW()-2<Settings!$B$12),NA(),IF(COUNT(OFFSET(F7,1-Settings!$B$12,0,Settings!$B$12,1))<ROUNDUP(Settings!$B$12*Settings!$B$26,0),NA(),STDEV(OFFSET(F7,1-Settings!$B$12,0,Settings!$B$12,1))*SQRT(Settings!$B$13))) | J7: =IF(OR(NOT(ISNUMBER($A7)),ROW()-2<Settings!$B$11),NA(),IF(COUNT(OFFSET(G7,1-Settings!$B$11,0,Settings!$B$11,1))<ROUNDUP(Settings!$B$11*Settings!$B$26,0),NA(),STDEV(OFFSET(G7,1-Settings!$B$11,0,Settings!$B$11,1))*SQRT(Settings!$B$13))) | K7: =IF(OR(NOT(ISNUMBER($A7)),ROW()-2<Settings!$B$12),NA(),IF(COUNT(OFFSET(G7,1-Settings!$B$12,0,Settings!$B$12,1))<ROUNDUP(Settings!$B$12*Settings!$B$26,0),NA(),STDEV(OFFSET(G7,1-Settings!$B$12,0,Settings!$B$12,1))*SQRT(Settings!$B$13))) | L7: =IF(AND(ISNUMBER(D7),ISNUMBER(H7)),D7-H7,NA()) | M7: =IF(AND(ISNUMBER(E7),ISNUMBER(K7)),E7-K7,NA()) | N7: =IF(NOT(ISNUMBER($A7)),NA(),IF(COUNT(OFFSET(G7,1,0,Settings!$B$12,1))<ROUNDUP(Settings!$B$12*Settings!$B$26,0),NA(),STDEV(OFFSET(G7,1,0,Settings!$B$12,1))*SQRT(Settings!$B$13))) | O7: =IF(AND(ISNUMBER(E7),ISNUMBER(N7)),E7-N7,NA()) | P7: =IF(NOT(ISNUMBER($A7)),NA(),IF(OR($A7<MIN(KW_TP!$A$2:$A$2501),$A7>MAX(KW_TP!$A$2:$A$2501)),NA(),INDEX(KW_TP!$C$2:$C$2501,MATCH($A7,KW_TP!$A$2:$A$2501,1)))) | Q7: =IF(NOT(ISNUMBER($A7)),NA(),IFERROR(1*INDEX(BBG_Data!$J$2:$J$4000,MATCH($A7,BBG_Data!$I$2:$I$4000,0)),NA())) | R7: =IF(NOT(ISNUMBER($A7)),NA(),IFERROR(1*INDEX(BBG_Data!$L$2:$L$4000,MATCH($A7,BBG_Data!$K$2:$K$4000,0)),NA())) | S7: =IF(AND(ISNUMBER(B7),ISNUMBER(Q7),ISNUMBER(R7)),(B7-Q7-R7)*100,NA()) | T7: =IF(AND(ISNUMBER(B7),Settings!$B$17>0),IF(ISNUMBER(INDEX($B:$B,Settings!$B$17)),(B7-INDEX($B:$B,Settings!$B$17))*100,NA()),NA()) | U7: =IF(AND(ISNUMBER(Q7),Settings!$B$17>0),IF(ISNUMBER(INDEX($Q:$Q,Settings!$B$17)),(Q7-INDEX($Q:$Q,Settings!$B$17))*100,NA()),NA()) | V7: =IF(AND(ISNUMBER(R7),Settings!$B$17>0),IF(ISNUMBER(INDEX($R:$R,Settings!$B$17)),(R7-INDEX($R:$R,Settings!$B$17))*100,NA()),NA()) | W7: =IF(AND(ISNUMBER(P7),Settings!$B$17>0),IF(ISNUMBER(INDEX($P:$P,Settings!$B$17)),P7-INDEX($P:$P,Settings!$B$17),NA()),NA()) | X7: =IF(NOT(ISNUMBER($A7)),NA(),IF(OR($A7<MIN(DKW_10Y!$A$2:$A$2918),$A7>MAX(DKW_10Y!$A$2:$A$2918),Settings!$B$16<MIN(DKW_10Y!$A$2:$A$2918)),NA(),(INDEX(DKW_10Y!$B$2:$B$2918,MATCH($A7,DKW_10Y!$A$2:$A$2918,1))-INDEX(DKW_10Y!$B$2:$B$2918,MATCH(Settings!$B$16,DKW_10Y!$A$2:$A$2918,1)))*100)) | Y7: =IF(NOT(ISNUMBER($A7)),NA(),IF(OR($A7<MIN(DKW_10Y!$A$2:$A$2918),$A7>MAX(DKW_10Y!$A$2:$A$2918),Settings!$B$16<MIN(DKW_10Y!$A$2:$A$2918)),NA(),(INDEX(DKW_10Y!$C$2:$C$2918,MATCH($A7,DKW_10Y!$A$2:$A$2918,1))-INDEX(DKW_10Y!$C$2:$C$2918,MATCH(Settings!$B$16,DKW_10Y!$A$2:$A$2918,1)))*100)) | Z7: =IF(NOT(ISNUMBER($A7)),NA(),IF(OR($A7<MIN(DKW_10Y!$A$2:$A$2918),$A7>MAX(DKW_10Y!$A$2:$A$2918),Settings!$B$16<MIN(DKW_10Y!$A$2:$A$2918)),NA(),(INDEX(DKW_10Y!$D$2:$D$2918,MATCH($A7,DKW_10Y!$A$2:$A$2918,1))-INDEX(DKW_10Y!$D$2:$D$2918,MATCH(Settings!$B$16,DKW_10Y!$A$2:$A$2918,1)))*100)) | AA7: =IF(NOT(ISNUMBER($A7)),NA(),IF(OR($A7<MIN(DKW_10Y!$A$2:$A$2918),$A7>MAX(DKW_10Y!$A$2:$A$2918),Settings!$B$16<MIN(DKW_10Y!$A$2:$A$2918)),NA(),(INDEX(DKW_10Y!$E$2:$E$2918,MATCH($A7,DKW_10Y!$A$2:$A$2918,1))-INDEX(DKW_10Y!$E$2:$E$2918,MATCH(Settings!$B$16,DKW_10Y!$A$2:$A$2918,1)))*100)) | AB7: =IF(NOT(ISNUMBER($A7)),NA(),IF(OR($A7<MIN(DKW_10Y!$A$2:$A$2918),$A7>MAX(DKW_10Y!$A$2:$A$2918),Settings!$B$16<MIN(DKW_10Y!$A$2:$A$2918)),NA(),(INDEX(DKW_10Y!$H$2:$H$2918,MATCH($A7,DKW_10Y!$A$2:$A$2918,1))-INDEX(DKW_10Y!$H$2:$H$2918,MATCH(Settings!$B$16,DKW_10Y!$A$2:$A$2918,1)))*100)) | AC7: =IF(NOT(ISNUMBER($A7)),NA(),IFERROR(1*INDEX(BBG_Data!$N$2:$N$4000,MATCH($A7,BBG_Data!$M$2:$M$4000,0)),NA())) | AD7: =IF(NOT(ISNUMBER($A7)),NA(),IFERROR(1*INDEX(BBG_Data!$P$2:$P$4000,MATCH($A7,BBG_Data!$O$2:$O$4000,0)),NA())) | AE7: =IF(NOT(ISNUMBER($A7)),NA(),IFERROR(1*INDEX(BBG_Data!$R$2:$R$4000,MATCH($A7,BBG_Data!$Q$2:$Q$4000,0)),NA())) | AF7: =IF(AND(ISNUMBER(B7),ISNUMBER(AC7)),(B7-AC7)*100,NA()) | AG7: =IF(AND(ISNUMBER(AE7),ISNUMBER(AD7)),(AE7-AD7)*100,NA()) | AH7: =IF(NOT(ISNUMBER($A7)),NA(),IFERROR(INDEX(BBG_Data!$T$2:$T$4000,MATCH($A7,BBG_Data!$S$2:$S$4000,0))*Settings!$B$25,NA())) | AI7: =IF(NOT(ISNUMBER($A7)),NA(),IFERROR(INDEX(BBG_Data!$V$2:$V$4000,MATCH($A7,BBG_Data!$U$2:$U$4000,0))*Settings!$B$25,NA())) | AJ7: =IF(NOT(ISNUMBER($A7)),NA(),IFERROR(1*INDEX(BBG_Data!$X$2:$X$4000,MATCH($A7,BBG_Data!$W$2:$W$4000,0)),NA())) | AK7: =IF(NOT(ISNUMBER($A7)),NA(),IFERROR(1*INDEX(BBG_Data!$Z$2:$Z$4000,MATCH($A7,BBG_Data!$Y$2:$Y$4000,0)),NA()))
A8: =IF(ISNUMBER(BBG_Data!A8),BBG_Data!A8,"") | B8: =IF(AND(ISNUMBER($A8),ISNUMBER(BBG_Data!B8)),BBG_Data!B8,NA()) | C8: =IF(NOT(ISNUMBER($A8)),NA(),IFERROR(1*INDEX(BBG_Data!$D$2:$D$4000,MATCH($A8,BBG_Data!$C$2:$C$4000,0)),NA())) | D8: =IF(NOT(ISNUMBER($A8)),NA(),IFERROR(1*INDEX(BBG_Data!$F$2:$F$4000,MATCH($A8,BBG_Data!$E$2:$E$4000,0)),NA())) | E8: =IF(NOT(ISNUMBER($A8)),NA(),IFERROR(1*INDEX(BBG_Data!$H$2:$H$4000,MATCH($A8,BBG_Data!$G$2:$G$4000,0)),NA())) | F8: =IF(AND(ISNUMBER(B8),ISNUMBER(B7)),IF(B8=B7,"",(B8-B7)*100),"") | G8: =IF(AND(ISNUMBER(C8),ISNUMBER(C7)),IF(C8=C7,"",(C8-C7)*100),"") | H8: =IF(OR(NOT(ISNUMBER($A8)),ROW()-2<Settings!$B$11),NA(),IF(COUNT(OFFSET(F8,1-Settings!$B$11,0,Settings!$B$11,1))<ROUNDUP(Settings!$B$11*Settings!$B$26,0),NA(),STDEV(OFFSET(F8,1-Settings!$B$11,0,Settings!$B$11,1))*SQRT(Settings!$B$13))) | I8: =IF(OR(NOT(ISNUMBER($A8)),ROW()-2<Settings!$B$12),NA(),IF(COUNT(OFFSET(F8,1-Settings!$B$12,0,Settings!$B$12,1))<ROUNDUP(Settings!$B$12*Settings!$B$26,0),NA(),STDEV(OFFSET(F8,1-Settings!$B$12,0,Settings!$B$12,1))*SQRT(Settings!$B$13))) | J8: =IF(OR(NOT(ISNUMBER($A8)),ROW()-2<Settings!$B$11),NA(),IF(COUNT(OFFSET(G8,1-Settings!$B$11,0,Settings!$B$11,1))<ROUNDUP(Settings!$B$11*Settings!$B$26,0),NA(),STDEV(OFFSET(G8,1-Settings!$B$11,0,Settings!$B$11,1))*SQRT(Settings!$B$13))) | K8: =IF(OR(NOT(ISNUMBER($A8)),ROW()-2<Settings!$B$12),NA(),IF(COUNT(OFFSET(G8,1-Settings!$B$12,0,Settings!$B$12,1))<ROUNDUP(Settings!$B$12*Settings!$B$26,0),NA(),STDEV(OFFSET(G8,1-Settings!$B$12,0,Settings!$B$12,1))*SQRT(Settings!$B$13))) | L8: =IF(AND(ISNUMBER(D8),ISNUMBER(H8)),D8-H8,NA()) | M8: =IF(AND(ISNUMBER(E8),ISNUMBER(K8)),E8-K8,NA()) | N8: =IF(NOT(ISNUMBER($A8)),NA(),IF(COUNT(OFFSET(G8,1,0,Settings!$B$12,1))<ROUNDUP(Settings!$B$12*Settings!$B$26,0),NA(),STDEV(OFFSET(G8,1,0,Settings!$B$12,1))*SQRT(Settings!$B$13))) | O8: =IF(AND(ISNUMBER(E8),ISNUMBER(N8)),E8-N8,NA()) | P8: =IF(NOT(ISNUMBER($A8)),NA(),IF(OR($A8<MIN(KW_TP!$A$2:$A$2501),$A8>MAX(KW_TP!$A$2:$A$2501)),NA(),INDEX(KW_TP!$C$2:$C$2501,MATCH($A8,KW_TP!$A$2:$A$2501,1)))) | Q8: =IF(NOT(ISNUMBER($A8)),NA(),IFERROR(1*INDEX(BBG_Data!$J$2:$J$4000,MATCH($A8,BBG_Data!$I$2:$I$4000,0)),NA())) | R8: =IF(NOT(ISNUMBER($A8)),NA(),IFERROR(1*INDEX(BBG_Data!$L$2:$L$4000,MATCH($A8,BBG_Data!$K$2:$K$4000,0)),NA())) | S8: =IF(AND(ISNUMBER(B8),ISNUMBER(Q8),ISNUMBER(R8)),(B8-Q8-R8)*100,NA()) | T8: =IF(AND(ISNUMBER(B8),Settings!$B$17>0),IF(ISNUMBER(INDEX($B:$B,Settings!$B$17)),(B8-INDEX($B:$B,Settings!$B$17))*100,NA()),NA()) | U8: =IF(AND(ISNUMBER(Q8),Settings!$B$17>0),IF(ISNUMBER(INDEX($Q:$Q,Settings!$B$17)),(Q8-INDEX($Q:$Q,Settings!$B$17))*100,NA()),NA()) | V8: =IF(AND(ISNUMBER(R8),Settings!$B$17>0),IF(ISNUMBER(INDEX($R:$R,Settings!$B$17)),(R8-INDEX($R:$R,Settings!$B$17))*100,NA()),NA()) | W8: =IF(AND(ISNUMBER(P8),Settings!$B$17>0),IF(ISNUMBER(INDEX($P:$P,Settings!$B$17)),P8-INDEX($P:$P,Settings!$B$17),NA()),NA()) | X8: =IF(NOT(ISNUMBER($A8)),NA(),IF(OR($A8<MIN(DKW_10Y!$A$2:$A$2918),$A8>MAX(DKW_10Y!$A$2:$A$2918),Settings!$B$16<MIN(DKW_10Y!$A$2:$A$2918)),NA(),(INDEX(DKW_10Y!$B$2:$B$2918,MATCH($A8,DKW_10Y!$A$2:$A$2918,1))-INDEX(DKW_10Y!$B$2:$B$2918,MATCH(Settings!$B$16,DKW_10Y!$A$2:$A$2918,1)))*100)) | Y8: =IF(NOT(ISNUMBER($A8)),NA(),IF(OR($A8<MIN(DKW_10Y!$A$2:$A$2918),$A8>MAX(DKW_10Y!$A$2:$A$2918),Settings!$B$16<MIN(DKW_10Y!$A$2:$A$2918)),NA(),(INDEX(DKW_10Y!$C$2:$C$2918,MATCH($A8,DKW_10Y!$A$2:$A$2918,1))-INDEX(DKW_10Y!$C$2:$C$2918,MATCH(Settings!$B$16,DKW_10Y!$A$2:$A$2918,1)))*100)) | Z8: =IF(NOT(ISNUMBER($A8)),NA(),IF(OR($A8<MIN(DKW_10Y!$A$2:$A$2918),$A8>MAX(DKW_10Y!$A$2:$A$2918),Settings!$B$16<MIN(DKW_10Y!$A$2:$A$2918)),NA(),(INDEX(DKW_10Y!$D$2:$D$2918,MATCH($A8,DKW_10Y!$A$2:$A$2918,1))-INDEX(DKW_10Y!$D$2:$D$2918,MATCH(Settings!$B$16,DKW_10Y!$A$2:$A$2918,1)))*100)) | AA8: =IF(NOT(ISNUMBER($A8)),NA(),IF(OR($A8<MIN(DKW_10Y!$A$2:$A$2918),$A8>MAX(DKW_10Y!$A$2:$A$2918),Settings!$B$16<MIN(DKW_10Y!$A$2:$A$2918)),NA(),(INDEX(DKW_10Y!$E$2:$E$2918,MATCH($A8,DKW_10Y!$A$2:$A$2918,1))-INDEX(DKW_10Y!$E$2:$E$2918,MATCH(Settings!$B$16,DKW_10Y!$A$2:$A$2918,1)))*100)) | AB8: =IF(NOT(ISNUMBER($A8)),NA(),IF(OR($A8<MIN(DKW_10Y!$A$2:$A$2918),$A8>MAX(DKW_10Y!$A$2:$A$2918),Settings!$B$16<MIN(DKW_10Y!$A$2:$A$2918)),NA(),(INDEX(DKW_10Y!$H$2:$H$2918,MATCH($A8,DKW_10Y!$A$2:$A$2918,1))-INDEX(DKW_10Y!$H$2:$H$2918,MATCH(Settings!$B$16,DKW_10Y!$A$2:$A$2918,1)))*100)) | AC8: =IF(NOT(ISNUMBER($A8)),NA(),IFERROR(1*INDEX(BBG_Data!$N$2:$N$4000,MATCH($A8,BBG_Data!$M$2:$M$4000,0)),NA())) | AD8: =IF(NOT(ISNUMBER($A8)),NA(),IFERROR(1*INDEX(BBG_Data!$P$2:$P$4000,MATCH($A8,BBG_Data!$O$2:$O$4000,0)),NA())) | AE8: =IF(NOT(ISNUMBER($A8)),NA(),IFERROR(1*INDEX(BBG_Data!$R$2:$R$4000,MATCH($A8,BBG_Data!$Q$2:$Q$4000,0)),NA())) | AF8: =IF(AND(ISNUMBER(B8),ISNUMBER(AC8)),(B8-AC8)*100,NA()) | AG8: =IF(AND(ISNUMBER(AE8),ISNUMBER(AD8)),(AE8-AD8)*100,NA()) | AH8: =IF(NOT(ISNUMBER($A8)),NA(),IFERROR(INDEX(BBG_Data!$T$2:$T$4000,MATCH($A8,BBG_Data!$S$2:$S$4000,0))*Settings!$B$25,NA())) | AI8: =IF(NOT(ISNUMBER($A8)),NA(),IFERROR(INDEX(BBG_Data!$V$2:$V$4000,MATCH($A8,BBG_Data!$U$2:$U$4000,0))*Settings!$B$25,NA())) | AJ8: =IF(NOT(ISNUMBER($A8)),NA(),IFERROR(1*INDEX(BBG_Data!$X$2:$X$4000,MATCH($A8,BBG_Data!$W$2:$W$4000,0)),NA())) | AK8: =IF(NOT(ISNUMBER($A8)),NA(),IFERROR(1*INDEX(BBG_Data!$Z$2:$Z$4000,MATCH($A8,BBG_Data!$Y$2:$Y$4000,0)),NA()))
A9: =IF(ISNUMBER(BBG_Data!A9),BBG_Data!A9,"") | B9: =IF(AND(ISNUMBER($A9),ISNUMBER(BBG_Data!B9)),BBG_Data!B9,NA()) | C9: =IF(NOT(ISNUMBER($A9)),NA(),IFERROR(1*INDEX(BBG_Data!$D$2:$D$4000,MATCH($A9,BBG_Data!$C$2:$C$4000,0)),NA())) | D9: =IF(NOT(ISNUMBER($A9)),NA(),IFERROR(1*INDEX(BBG_Data!$F$2:$F$4000,MATCH($A9,BBG_Data!$E$2:$E$4000,0)),NA())) | E9: =IF(NOT(ISNUMBER($A9)),NA(),IFERROR(1*INDEX(BBG_Data!$H$2:$H$4000,MATCH($A9,BBG_Data!$G$2:$G$4000,0)),NA())) | F9: =IF(AND(ISNUMBER(B9),ISNUMBER(B8)),IF(B9=B8,"",(B9-B8)*100),"") | G9: =IF(AND(ISNUMBER(C9),ISNUMBER(C8)),IF(C9=C8,"",(C9-C8)*100),"") | H9: =IF(OR(NOT(ISNUMBER($A9)),ROW()-2<Settings!$B$11),NA(),IF(COUNT(OFFSET(F9,1-Settings!$B$11,0,Settings!$B$11,1))<ROUNDUP(Settings!$B$11*Settings!$B$26,0),NA(),STDEV(OFFSET(F9,1-Settings!$B$11,0,Settings!$B$11,1))*SQRT(Settings!$B$13))) | I9: =IF(OR(NOT(ISNUMBER($A9)),ROW()-2<Settings!$B$12),NA(),IF(COUNT(OFFSET(F9,1-Settings!$B$12,0,Settings!$B$12,1))<ROUNDUP(Settings!$B$12*Settings!$B$26,0),NA(),STDEV(OFFSET(F9,1-Settings!$B$12,0,Settings!$B$12,1))*SQRT(Settings!$B$13))) | J9: =IF(OR(NOT(ISNUMBER($A9)),ROW()-2<Settings!$B$11),NA(),IF(COUNT(OFFSET(G9,1-Settings!$B$11,0,Settings!$B$11,1))<ROUNDUP(Settings!$B$11*Settings!$B$26,0),NA(),STDEV(OFFSET(G9,1-Settings!$B$11,0,Settings!$B$11,1))*SQRT(Settings!$B$13))) | K9: =IF(OR(NOT(ISNUMBER($A9)),ROW()-2<Settings!$B$12),NA(),IF(COUNT(OFFSET(G9,1-Settings!$B$12,0,Settings!$B$12,1))<ROUNDUP(Settings!$B$12*Settings!$B$26,0),NA(),STDEV(OFFSET(G9,1-Settings!$B$12,0,Settings!$B$12,1))*SQRT(Settings!$B$13))) | L9: =IF(AND(ISNUMBER(D9),ISNUMBER(H9)),D9-H9,NA()) | M9: =IF(AND(ISNUMBER(E9),ISNUMBER(K9)),E9-K9,NA()) | N9: =IF(NOT(ISNUMBER($A9)),NA(),IF(COUNT(OFFSET(G9,1,0,Settings!$B$12,1))<ROUNDUP(Settings!$B$12*Settings!$B$26,0),NA(),STDEV(OFFSET(G9,1,0,Settings!$B$12,1))*SQRT(Settings!$B$13))) | O9: =IF(AND(ISNUMBER(E9),ISNUMBER(N9)),E9-N9,NA()) | P9: =IF(NOT(ISNUMBER($A9)),NA(),IF(OR($A9<MIN(KW_TP!$A$2:$A$2501),$A9>MAX(KW_TP!$A$2:$A$2501)),NA(),INDEX(KW_TP!$C$2:$C$2501,MATCH($A9,KW_TP!$A$2:$A$2501,1)))) | Q9: =IF(NOT(ISNUMBER($A9)),NA(),IFERROR(1*INDEX(BBG_Data!$J$2:$J$4000,MATCH($A9,BBG_Data!$I$2:$I$4000,0)),NA())) | R9: =IF(NOT(ISNUMBER($A9)),NA(),IFERROR(1*INDEX(BBG_Data!$L$2:$L$4000,MATCH($A9,BBG_Data!$K$2:$K$4000,0)),NA())) | S9: =IF(AND(ISNUMBER(B9),ISNUMBER(Q9),ISNUMBER(R9)),(B9-Q9-R9)*100,NA()) | T9: =IF(AND(ISNUMBER(B9),Settings!$B$17>0),IF(ISNUMBER(INDEX($B:$B,Settings!$B$17)),(B9-INDEX($B:$B,Settings!$B$17))*100,NA()),NA()) | U9: =IF(AND(ISNUMBER(Q9),Settings!$B$17>0),IF(ISNUMBER(INDEX($Q:$Q,Settings!$B$17)),(Q9-INDEX($Q:$Q,Settings!$B$17))*100,NA()),NA()) | V9: =IF(AND(ISNUMBER(R9),Settings!$B$17>0),IF(ISNUMBER(INDEX($R:$R,Settings!$B$17)),(R9-INDEX($R:$R,Settings!$B$17))*100,NA()),NA()) | W9: =IF(AND(ISNUMBER(P9),Settings!$B$17>0),IF(ISNUMBER(INDEX($P:$P,Settings!$B$17)),P9-INDEX($P:$P,Settings!$B$17),NA()),NA()) | X9: =IF(NOT(ISNUMBER($A9)),NA(),IF(OR($A9<MIN(DKW_10Y!$A$2:$A$2918),$A9>MAX(DKW_10Y!$A$2:$A$2918),Settings!$B$16<MIN(DKW_10Y!$A$2:$A$2918)),NA(),(INDEX(DKW_10Y!$B$2:$B$2918,MATCH($A9,DKW_10Y!$A$2:$A$2918,1))-INDEX(DKW_10Y!$B$2:$B$2918,MATCH(Settings!$B$16,DKW_10Y!$A$2:$A$2918,1)))*100)) | Y9: =IF(NOT(ISNUMBER($A9)),NA(),IF(OR($A9<MIN(DKW_10Y!$A$2:$A$2918),$A9>MAX(DKW_10Y!$A$2:$A$2918),Settings!$B$16<MIN(DKW_10Y!$A$2:$A$2918)),NA(),(INDEX(DKW_10Y!$C$2:$C$2918,MATCH($A9,DKW_10Y!$A$2:$A$2918,1))-INDEX(DKW_10Y!$C$2:$C$2918,MATCH(Settings!$B$16,DKW_10Y!$A$2:$A$2918,1)))*100)) | Z9: =IF(NOT(ISNUMBER($A9)),NA(),IF(OR($A9<MIN(DKW_10Y!$A$2:$A$2918),$A9>MAX(DKW_10Y!$A$2:$A$2918),Settings!$B$16<MIN(DKW_10Y!$A$2:$A$2918)),NA(),(INDEX(DKW_10Y!$D$2:$D$2918,MATCH($A9,DKW_10Y!$A$2:$A$2918,1))-INDEX(DKW_10Y!$D$2:$D$2918,MATCH(Settings!$B$16,DKW_10Y!$A$2:$A$2918,1)))*100)) | AA9: =IF(NOT(ISNUMBER($A9)),NA(),IF(OR($A9<MIN(DKW_10Y!$A$2:$A$2918),$A9>MAX(DKW_10Y!$A$2:$A$2918),Settings!$B$16<MIN(DKW_10Y!$A$2:$A$2918)),NA(),(INDEX(DKW_10Y!$E$2:$E$2918,MATCH($A9,DKW_10Y!$A$2:$A$2918,1))-INDEX(DKW_10Y!$E$2:$E$2918,MATCH(Settings!$B$16,DKW_10Y!$A$2:$A$2918,1)))*100)) | AB9: =IF(NOT(ISNUMBER($A9)),NA(),IF(OR($A9<MIN(DKW_10Y!$A$2:$A$2918),$A9>MAX(DKW_10Y!$A$2:$A$2918),Settings!$B$16<MIN(DKW_10Y!$A$2:$A$2918)),NA(),(INDEX(DKW_10Y!$H$2:$H$2918,MATCH($A9,DKW_10Y!$A$2:$A$2918,1))-INDEX(DKW_10Y!$H$2:$H$2918,MATCH(Settings!$B$16,DKW_10Y!$A$2:$A$2918,1)))*100)) | AC9: =IF(NOT(ISNUMBER($A9)),NA(),IFERROR(1*INDEX(BBG_Data!$N$2:$N$4000,MATCH($A9,BBG_Data!$M$2:$M$4000,0)),NA())) | AD9: =IF(NOT(ISNUMBER($A9)),NA(),IFERROR(1*INDEX(BBG_Data!$P$2:$P$4000,MATCH($A9,BBG_Data!$O$2:$O$4000,0)),NA())) | AE9: =IF(NOT(ISNUMBER($A9)),NA(),IFERROR(1*INDEX(BBG_Data!$R$2:$R$4000,MATCH($A9,BBG_Data!$Q$2:$Q$4000,0)),NA())) | AF9: =IF(AND(ISNUMBER(B9),ISNUMBER(AC9)),(B9-AC9)*100,NA()) | AG9: =IF(AND(ISNUMBER(AE9),ISNUMBER(AD9)),(AE9-AD9)*100,NA()) | AH9: =IF(NOT(ISNUMBER($A9)),NA(),IFERROR(INDEX(BBG_Data!$T$2:$T$4000,MATCH($A9,BBG_Data!$S$2:$S$4000,0))*Settings!$B$25,NA())) | AI9: =IF(NOT(ISNUMBER($A9)),NA(),IFERROR(INDEX(BBG_Data!$V$2:$V$4000,MATCH($A9,BBG_Data!$U$2:$U$4000,0))*Settings!$B$25,NA())) | AJ9: =IF(NOT(ISNUMBER($A9)),NA(),IFERROR(1*INDEX(BBG_Data!$X$2:$X$4000,MATCH($A9,BBG_Data!$W$2:$W$4000,0)),NA())) | AK9: =IF(NOT(ISNUMBER($A9)),NA(),IFERROR(1*INDEX(BBG_Data!$Z$2:$Z$4000,MATCH($A9,BBG_Data!$Y$2:$Y$4000,0)),NA()))
A10: =IF(ISNUMBER(BBG_Data!A10),BBG_Data!A10,"") | B10: =IF(AND(ISNUMBER($A10),ISNUMBER(BBG_Data!B10)),BBG_Data!B10,NA()) | C10: =IF(NOT(ISNUMBER($A10)),NA(),IFERROR(1*INDEX(BBG_Data!$D$2:$D$4000,MATCH($A10,BBG_Data!$C$2:$C$4000,0)),NA())) | D10: =IF(NOT(ISNUMBER($A10)),NA(),IFERROR(1*INDEX(BBG_Data!$F$2:$F$4000,MATCH($A10,BBG_Data!$E$2:$E$4000,0)),NA())) | E10: =IF(NOT(ISNUMBER($A10)),NA(),IFERROR(1*INDEX(BBG_Data!$H$2:$H$4000,MATCH($A10,BBG_Data!$G$2:$G$4000,0)),NA())) | F10: =IF(AND(ISNUMBER(B10),ISNUMBER(B9)),IF(B10=B9,"",(B10-B9)*100),"") | G10: =IF(AND(ISNUMBER(C10),ISNUMBER(C9)),IF(C10=C9,"",(C10-C9)*100),"") | H10: =IF(OR(NOT(ISNUMBER($A10)),ROW()-2<Settings!$B$11),NA(),IF(COUNT(OFFSET(F10,1-Settings!$B$11,0,Settings!$B$11,1))<ROUNDUP(Settings!$B$11*Settings!$B$26,0),NA(),STDEV(OFFSET(F10,1-Settings!$B$11,0,Settings!$B$11,1))*SQRT(Settings!$B$13))) | I10: =IF(OR(NOT(ISNUMBER($A10)),ROW()-2<Settings!$B$12),NA(),IF(COUNT(OFFSET(F10,1-Settings!$B$12,0,Settings!$B$12,1))<ROUNDUP(Settings!$B$12*Settings!$B$26,0),NA(),STDEV(OFFSET(F10,1-Settings!$B$12,0,Settings!$B$12,1))*SQRT(Settings!$B$13))) | J10: =IF(OR(NOT(ISNUMBER($A10)),ROW()-2<Settings!$B$11),NA(),IF(COUNT(OFFSET(G10,1-Settings!$B$11,0,Settings!$B$11,1))<ROUNDUP(Settings!$B$11*Settings!$B$26,0),NA(),STDEV(OFFSET(G10,1-Settings!$B$11,0,Settings!$B$11,1))*SQRT(Settings!$B$13))) | K10: =IF(OR(NOT(ISNUMBER($A10)),ROW()-2<Settings!$B$12),NA(),IF(COUNT(OFFSET(G10,1-Settings!$B$12,0,Settings!$B$12,1))<ROUNDUP(Settings!$B$12*Settings!$B$26,0),NA(),STDEV(OFFSET(G10,1-Settings!$B$12,0,Settings!$B$12,1))*SQRT(Settings!$B$13))) | L10: =IF(AND(ISNUMBER(D10),ISNUMBER(H10)),D10-H10,NA()) | M10: =IF(AND(ISNUMBER(E10),ISNUMBER(K10)),E10-K10,NA()) | N10: =IF(NOT(ISNUMBER($A10)),NA(),IF(COUNT(OFFSET(G10,1,0,Settings!$B$12,1))<ROUNDUP(Settings!$B$12*Settings!$B$26,0),NA(),STDEV(OFFSET(G10,1,0,Settings!$B$12,1))*SQRT(Settings!$B$13))) | O10: =IF(AND(ISNUMBER(E10),ISNUMBER(N10)),E10-N10,NA()) | P10: =IF(NOT(ISNUMBER($A10)),NA(),IF(OR($A10<MIN(KW_TP!$A$2:$A$2501),$A10>MAX(KW_TP!$A$2:$A$2501)),NA(),INDEX(KW_TP!$C$2:$C$2501,MATCH($A10,KW_TP!$A$2:$A$2501,1)))) | Q10: =IF(NOT(ISNUMBER($A10)),NA(),IFERROR(1*INDEX(BBG_Data!$J$2:$J$4000,MATCH($A10,BBG_Data!$I$2:$I$4000,0)),NA())) | R10: =IF(NOT(ISNUMBER($A10)),NA(),IFERROR(1*INDEX(BBG_Data!$L$2:$L$4000,MATCH($A10,BBG_Data!$K$2:$K$4000,0)),NA())) | S10: =IF(AND(ISNUMBER(B10),ISNUMBER(Q10),ISNUMBER(R10)),(B10-Q10-R10)*100,NA()) | T10: =IF(AND(ISNUMBER(B10),Settings!$B$17>0),IF(ISNUMBER(INDEX($B:$B,Settings!$B$17)),(B10-INDEX($B:$B,Settings!$B$17))*100,NA()),NA()) | U10: =IF(AND(ISNUMBER(Q10),Settings!$B$17>0),IF(ISNUMBER(INDEX($Q:$Q,Settings!$B$17)),(Q10-INDEX($Q:$Q,Settings!$B$17))*100,NA()),NA()) | V10: =IF(AND(ISNUMBER(R10),Settings!$B$17>0),IF(ISNUMBER(INDEX($R:$R,Settings!$B$17)),(R10-INDEX($R:$R,Settings!$B$17))*100,NA()),NA()) | W10: =IF(AND(ISNUMBER(P10),Settings!$B$17>0),IF(ISNUMBER(INDEX($P:$P,Settings!$B$17)),P10-INDEX($P:$P,Settings!$B$17),NA()),NA()) | X10: =IF(NOT(ISNUMBER($A10)),NA(),IF(OR($A10<MIN(DKW_10Y!$A$2:$A$2918),$A10>MAX(DKW_10Y!$A$2:$A$2918),Settings!$B$16<MIN(DKW_10Y!$A$2:$A$2918)),NA(),(INDEX(DKW_10Y!$B$2:$B$2918,MATCH($A10,DKW_10Y!$A$2:$A$2918,1))-INDEX(DKW_10Y!$B$2:$B$2918,MATCH(Settings!$B$16,DKW_10Y!$A$2:$A$2918,1)))*100)) | Y10: =IF(NOT(ISNUMBER($A10)),NA(),IF(OR($A10<MIN(DKW_10Y!$A$2:$A$2918),$A10>MAX(DKW_10Y!$A$2:$A$2918),Settings!$B$16<MIN(DKW_10Y!$A$2:$A$2918)),NA(),(INDEX(DKW_10Y!$C$2:$C$2918,MATCH($A10,DKW_10Y!$A$2:$A$2918,1))-INDEX(DKW_10Y!$C$2:$C$2918,MATCH(Settings!$B$16,DKW_10Y!$A$2:$A$2918,1)))*100)) | Z10: =IF(NOT(ISNUMBER($A10)),NA(),IF(OR($A10<MIN(DKW_10Y!$A$2:$A$2918),$A10>MAX(DKW_10Y!$A$2:$A$2918),Settings!$B$16<MIN(DKW_10Y!$A$2:$A$2918)),NA(),(INDEX(DKW_10Y!$D$2:$D$2918,MATCH($A10,DKW_10Y!$A$2:$A$2918,1))-INDEX(DKW_10Y!$D$2:$D$2918,MATCH(Settings!$B$16,DKW_10Y!$A$2:$A$2918,1)))*100)) | AA10: =IF(NOT(ISNUMBER($A10)),NA(),IF(OR($A10<MIN(DKW_10Y!$A$2:$A$2918),$A10>MAX(DKW_10Y!$A$2:$A$2918),Settings!$B$16<MIN(DKW_10Y!$A$2:$A$2918)),NA(),(INDEX(DKW_10Y!$E$2:$E$2918,MATCH($A10,DKW_10Y!$A$2:$A$2918,1))-INDEX(DKW_10Y!$E$2:$E$2918,MATCH(Settings!$B$16,DKW_10Y!$A$2:$A$2918,1)))*100)) | AB10: =IF(NOT(ISNUMBER($A10)),NA(),IF(OR($A10<MIN(DKW_10Y!$A$2:$A$2918),$A10>MAX(DKW_10Y!$A$2:$A$2918),Settings!$B$16<MIN(DKW_10Y!$A$2:$A$2918)),NA(),(INDEX(DKW_10Y!$H$2:$H$2918,MATCH($A10,DKW_10Y!$A$2:$A$2918,1))-INDEX(DKW_10Y!$H$2:$H$2918,MATCH(Settings!$B$16,DKW_10Y!$A$2:$A$2918,1)))*100)) | AC10: =IF(NOT(ISNUMBER($A10)),NA(),IFERROR(1*INDEX(BBG_Data!$N$2:$N$4000,MATCH($A10,BBG_Data!$M$2:$M$4000,0)),NA())) | AD10: =IF(NOT(ISNUMBER($A10)),NA(),IFERROR(1*INDEX(BBG_Data!$P$2:$P$4000,MATCH($A10,BBG_Data!$O$2:$O$4000,0)),NA())) | AE10: =IF(NOT(ISNUMBER($A10)),NA(),IFERROR(1*INDEX(BBG_Data!$R$2:$R$4000,MATCH($A10,BBG_Data!$Q$2:$Q$4000,0)),NA())) | AF10: =IF(AND(ISNUMBER(B10),ISNUMBER(AC10)),(B10-AC10)*100,NA()) | AG10: =IF(AND(ISNUMBER(AE10),ISNUMBER(AD10)),(AE10-AD10)*100,NA()) | AH10: =IF(NOT(ISNUMBER($A10)),NA(),IFERROR(INDEX(BBG_Data!$T$2:$T$4000,MATCH($A10,BBG_Data!$S$2:$S$4000,0))*Settings!$B$25,NA())) | AI10: =IF(NOT(ISNUMBER($A10)),NA(),IFERROR(INDEX(BBG_Data!$V$2:$V$4000,MATCH($A10,BBG_Data!$U$2:$U$4000,0))*Settings!$B$25,NA())) | AJ10: =IF(NOT(ISNUMBER($A10)),NA(),IFERROR(1*INDEX(BBG_Data!$X$2:$X$4000,MATCH($A10,BBG_Data!$W$2:$W$4000,0)),NA())) | AK10: =IF(NOT(ISNUMBER($A10)),NA(),IFERROR(1*INDEX(BBG_Data!$Z$2:$Z$4000,MATCH($A10,BBG_Data!$Y$2:$Y$4000,0)),NA()))
